[2025-04-19 09:05:34,984] DEBUG django.db.backends.schema: CREATE TABLE "django_migrations" ("id" bigint NOT NULL PRIMARY KEY GENERATED BY DEFAULT AS IDENTITY, "app" varchar(255) NOT NULL, "name" varchar(255) NOT NULL, "applied" timestamp with time zone NOT NULL); (params None)
[2025-04-19 09:05:34,994] DEBUG django.db.backends.schema: CREATE TABLE "django_content_type" ("id" integer NOT NULL PRIMARY KEY GENERATED BY DEFAULT AS IDENTITY, "name" varchar(100) NOT NULL, "app_label" varchar(100) NOT NULL, "model" varchar(100) NOT NULL); (params None)
[2025-04-19 09:05:35,001] DEBUG django.db.backends.schema: ALTER TABLE "django_content_type" ADD CONSTRAINT "django_content_type_app_label_model_76bd3d3b_uniq" UNIQUE ("app_label", "model"); (params None)
[2025-04-19 09:05:35,013] DEBUG django.db.backends.schema: ALTER TABLE "django_content_type" ALTER COLUMN "name" DROP NOT NULL; (params None)
[2025-04-19 09:05:35,016] DEBUG django.db.backends.schema: ALTER TABLE "django_content_type" DROP COLUMN "name" CASCADE; (params None)
[2025-04-19 09:05:35,020] DEBUG django.db.backends.schema: CREATE TABLE "auth_permission" ("id" integer NOT NULL PRIMARY KEY GENERATED BY DEFAULT AS IDENTITY, "name" varchar(50) NOT NULL, "content_type_id" integer NOT NULL, "codename" varchar(100) NOT NULL); (params None)
[2025-04-19 09:05:35,027] DEBUG django.db.backends.schema: CREATE TABLE "auth_group" ("id" integer NOT NULL PRIMARY KEY GENERATED BY DEFAULT AS IDENTITY, "name" varchar(80) NOT NULL UNIQUE); (params None)
[2025-04-19 09:05:35,032] DEBUG django.db.backends.schema: CREATE TABLE "auth_group_permissions" ("id" bigint NOT NULL PRIMARY KEY GENERATED BY DEFAULT AS IDENTITY, "group_id" integer NOT NULL, "permission_id" integer NOT NULL); (params None)
[2025-04-19 09:05:35,039] DEBUG django.db.backends.schema: ALTER TABLE "auth_permission" ADD CONSTRAINT "auth_permission_content_type_id_codename_01ab375a_uniq" UNIQUE ("content_type_id", "codename"); (params None)
[2025-04-19 09:05:35,042] DEBUG django.db.backends.schema: ALTER TABLE "auth_permission" ADD CONSTRAINT "auth_permission_content_type_id_2f476e4b_fk_django_co" FOREIGN KEY ("content_type_id") REFERENCES "django_content_type" ("id") DEFERRABLE INITIALLY DEFERRED; (params None)
[2025-04-19 09:05:35,045] DEBUG django.db.backends.schema: CREATE INDEX "auth_permission_content_type_id_2f476e4b" ON "auth_permission" ("content_type_id"); (params None)
[2025-04-19 09:05:35,047] DEBUG django.db.backends.schema: CREATE INDEX "auth_group_name_a6ea08ec_like" ON "auth_group" ("name" varchar_pattern_ops); (params None)
[2025-04-19 09:05:35,049] DEBUG django.db.backends.schema: ALTER TABLE "auth_group_permissions" ADD CONSTRAINT "auth_group_permissions_group_id_permission_id_0cd325b0_uniq" UNIQUE ("group_id", "permission_id"); (params None)
[2025-04-19 09:05:35,052] DEBUG django.db.backends.schema: ALTER TABLE "auth_group_permissions" ADD CONSTRAINT "auth_group_permissions_group_id_b120cbf9_fk_auth_group_id" FOREIGN KEY ("group_id") REFERENCES "auth_group" ("id") DEFERRABLE INITIALLY DEFERRED; (params None)
[2025-04-19 09:05:35,053] DEBUG django.db.backends.schema: ALTER TABLE "auth_group_permissions" ADD CONSTRAINT "auth_group_permissio_permission_id_84c5c92e_fk_auth_perm" FOREIGN KEY ("permission_id") REFERENCES "auth_permission" ("id") DEFERRABLE INITIALLY DEFERRED; (params None)
[2025-04-19 09:05:35,054] DEBUG django.db.backends.schema: CREATE INDEX "auth_group_permissions_group_id_b120cbf9" ON "auth_group_permissions" ("group_id"); (params None)
[2025-04-19 09:05:35,057] DEBUG django.db.backends.schema: CREATE INDEX "auth_group_permissions_permission_id_84c5c92e" ON "auth_group_permissions" ("permission_id"); (params None)
[2025-04-19 09:05:35,067] DEBUG django.db.backends.schema: ALTER TABLE "auth_permission" ALTER COLUMN "name" TYPE varchar(255); (params None)
[2025-04-19 09:05:35,104] DEBUG django.db.backends.schema: ALTER TABLE "auth_group" ALTER COLUMN "name" TYPE varchar(150); (params None)
[2025-04-19 09:05:35,123] DEBUG django.db.backends.schema: CREATE TABLE "user_customuser" ("id" bigint NOT NULL PRIMARY KEY GENERATED BY DEFAULT AS IDENTITY, "password" varchar(128) NOT NULL, "last_login" timestamp with time zone NULL, "is_superuser" boolean NOT NULL, "username" varchar(150) NOT NULL UNIQUE, "first_name" varchar(150) NOT NULL, "last_name" varchar(150) NOT NULL, "is_staff" boolean NOT NULL, "is_active" boolean NOT NULL, "date_joined" timestamp with time zone NOT NULL, "email" varchar(254) NOT NULL UNIQUE); (params None)
[2025-04-19 09:05:35,134] DEBUG django.db.backends.schema: CREATE TABLE "user_customuser_groups" ("id" bigint NOT NULL PRIMARY KEY GENERATED BY DEFAULT AS IDENTITY, "customuser_id" bigint NOT NULL, "group_id" integer NOT NULL); (params None)
[2025-04-19 09:05:35,137] DEBUG django.db.backends.schema: CREATE TABLE "user_customuser_user_permissions" ("id" bigint NOT NULL PRIMARY KEY GENERATED BY DEFAULT AS IDENTITY, "customuser_id" bigint NOT NULL, "permission_id" integer NOT NULL); (params None)
[2025-04-19 09:05:35,141] DEBUG django.db.backends.schema: CREATE INDEX "user_customuser_username_24be6f7e_like" ON "user_customuser" ("username" varchar_pattern_ops); (params None)
[2025-04-19 09:05:35,143] DEBUG django.db.backends.schema: CREATE INDEX "user_customuser_email_2292cf6d_like" ON "user_customuser" ("email" varchar_pattern_ops); (params None)
[2025-04-19 09:05:35,145] DEBUG django.db.backends.schema: ALTER TABLE "user_customuser_groups" ADD CONSTRAINT "user_customuser_groups_customuser_id_group_id_e0a2f621_uniq" UNIQUE ("customuser_id", "group_id"); (params None)
[2025-04-19 09:05:35,148] DEBUG django.db.backends.schema: ALTER TABLE "user_customuser_groups" ADD CONSTRAINT "user_customuser_grou_customuser_id_192632a7_fk_user_cust" FOREIGN KEY ("customuser_id") REFERENCES "user_customuser" ("id") DEFERRABLE INITIALLY DEFERRED; (params None)
[2025-04-19 09:05:35,150] DEBUG django.db.backends.schema: ALTER TABLE "user_customuser_groups" ADD CONSTRAINT "user_customuser_groups_group_id_bcbc9e48_fk_auth_group_id" FOREIGN KEY ("group_id") REFERENCES "auth_group" ("id") DEFERRABLE INITIALLY DEFERRED; (params None)
[2025-04-19 09:05:35,151] DEBUG django.db.backends.schema: CREATE INDEX "user_customuser_groups_customuser_id_192632a7" ON "user_customuser_groups" ("customuser_id"); (params None)
[2025-04-19 09:05:35,153] DEBUG django.db.backends.schema: CREATE INDEX "user_customuser_groups_group_id_bcbc9e48" ON "user_customuser_groups" ("group_id"); (params None)
[2025-04-19 09:05:35,156] DEBUG django.db.backends.schema: ALTER TABLE "user_customuser_user_permissions" ADD CONSTRAINT "user_customuser_user_per_customuser_id_permission_a5da865d_uniq" UNIQUE ("customuser_id", "permission_id"); (params None)
[2025-04-19 09:05:35,158] DEBUG django.db.backends.schema: ALTER TABLE "user_customuser_user_permissions" ADD CONSTRAINT "user_customuser_user_customuser_id_4552d9cc_fk_user_cust" FOREIGN KEY ("customuser_id") REFERENCES "user_customuser" ("id") DEFERRABLE INITIALLY DEFERRED; (params None)
[2025-04-19 09:05:35,159] DEBUG django.db.backends.schema: ALTER TABLE "user_customuser_user_permissions" ADD CONSTRAINT "user_customuser_user_permission_id_e57e8b9a_fk_auth_perm" FOREIGN KEY ("permission_id") REFERENCES "auth_permission" ("id") DEFERRABLE INITIALLY DEFERRED; (params None)
[2025-04-19 09:05:35,160] DEBUG django.db.backends.schema: CREATE INDEX "user_customuser_user_permissions_customuser_id_4552d9cc" ON "user_customuser_user_permissions" ("customuser_id"); (params None)
[2025-04-19 09:05:35,162] DEBUG django.db.backends.schema: CREATE INDEX "user_customuser_user_permissions_permission_id_e57e8b9a" ON "user_customuser_user_permissions" ("permission_id"); (params None)
[2025-04-19 09:05:35,175] DEBUG django.db.backends.schema: CREATE TABLE "django_admin_log" ("id" integer NOT NULL PRIMARY KEY GENERATED BY DEFAULT AS IDENTITY, "action_time" timestamp with time zone NOT NULL, "object_id" text NULL, "object_repr" varchar(200) NOT NULL, "action_flag" smallint NOT NULL CHECK ("action_flag" >= 0), "change_message" text NOT NULL, "content_type_id" integer NULL, "user_id" bigint NOT NULL); (params None)
[2025-04-19 09:05:35,181] DEBUG django.db.backends.schema: ALTER TABLE "django_admin_log" ADD CONSTRAINT "django_admin_log_content_type_id_c4bce8eb_fk_django_co" FOREIGN KEY ("content_type_id") REFERENCES "django_content_type" ("id") DEFERRABLE INITIALLY DEFERRED; (params None)
[2025-04-19 09:05:35,182] DEBUG django.db.backends.schema: ALTER TABLE "django_admin_log" ADD CONSTRAINT "django_admin_log_user_id_c564eba6_fk_user_customuser_id" FOREIGN KEY ("user_id") REFERENCES "user_customuser" ("id") DEFERRABLE INITIALLY DEFERRED; (params None)
[2025-04-19 09:05:35,183] DEBUG django.db.backends.schema: CREATE INDEX "django_admin_log_content_type_id_c4bce8eb" ON "django_admin_log" ("content_type_id"); (params None)
[2025-04-19 09:05:35,186] DEBUG django.db.backends.schema: CREATE INDEX "django_admin_log_user_id_c564eba6" ON "django_admin_log" ("user_id"); (params None)
[2025-04-19 09:05:35,205] DEBUG django.db.backends.schema: CREATE TABLE "admin_interface_theme" ("id" integer NOT NULL PRIMARY KEY GENERATED BY DEFAULT AS IDENTITY, "name" varchar(50) NOT NULL, "active" boolean NOT NULL, "title" varchar(50) NOT NULL, "title_visible" boolean NOT NULL, "logo" varchar(100) NOT NULL, "logo_visible" boolean NOT NULL, "css_header_background_color" varchar(10) NOT NULL, "css_header_title_color" varchar(10) NOT NULL, "css_header_text_color" varchar(10) NOT NULL, "css_header_link_color" varchar(10) NOT NULL, "css_header_link_hover_color" varchar(10) NOT NULL, "css_module_background_color" varchar(10) NOT NULL, "css_module_text_color" varchar(10) NOT NULL, "css_module_link_color" varchar(10) NOT NULL, "css_module_link_hover_color" varchar(10) NOT NULL, "css_module_rounded_corners" boolean NOT NULL, "css_generic_link_color" varchar(10) NOT NULL, "css_generic_link_hover_color" varchar(10) NOT NULL, "css_save_button_background_color" varchar(10) NOT NULL, "css_save_button_background_hover_color" varchar(10) NOT NULL, "css_save_button_text_color" varchar(10) NOT NULL, "css_delete_button_background_color" varchar(10) NOT NULL, "css_delete_button_background_hover_color" varchar(10) NOT NULL, "css_delete_button_text_color" varchar(10) NOT NULL, "css" text NOT NULL, "list_filter_dropdown" boolean NOT NULL); (params None)
[2025-04-19 09:05:35,217] DEBUG django.db.backends.schema: ALTER TABLE "admin_interface_theme" ADD COLUMN "related_modal_active" boolean DEFAULT true NOT NULL; (params None)
[2025-04-19 09:05:35,218] DEBUG django.db.backends.schema: ALTER TABLE "admin_interface_theme" ALTER COLUMN "related_modal_active" DROP DEFAULT; (params None)
[2025-04-19 09:05:35,221] DEBUG django.db.backends.schema: ALTER TABLE "admin_interface_theme" ADD COLUMN "related_modal_background_color" varchar(10) DEFAULT '#000000' NOT NULL; (params None)
[2025-04-19 09:05:35,222] DEBUG django.db.backends.schema: ALTER TABLE "admin_interface_theme" ALTER COLUMN "related_modal_background_color" DROP DEFAULT; (params None)
[2025-04-19 09:05:35,224] DEBUG django.db.backends.schema: ALTER TABLE "admin_interface_theme" ADD COLUMN "related_modal_background_opacity" double precision DEFAULT 0.2 NOT NULL; (params None)
[2025-04-19 09:05:35,225] DEBUG django.db.backends.schema: ALTER TABLE "admin_interface_theme" ALTER COLUMN "related_modal_background_opacity" DROP DEFAULT; (params None)
[2025-04-19 09:05:35,227] DEBUG django.db.backends.schema: ALTER TABLE "admin_interface_theme" ADD COLUMN "related_modal_rounded_corners" boolean DEFAULT true NOT NULL; (params None)
[2025-04-19 09:05:35,228] DEBUG django.db.backends.schema: ALTER TABLE "admin_interface_theme" ALTER COLUMN "related_modal_rounded_corners" DROP DEFAULT; (params None)
[2025-04-19 09:05:35,232] DEBUG django.db.backends.schema: ALTER TABLE "admin_interface_theme" ADD COLUMN "logo_color" varchar(10) DEFAULT '#FFFFFF' NOT NULL; (params None)
[2025-04-19 09:05:35,233] DEBUG django.db.backends.schema: ALTER TABLE "admin_interface_theme" ALTER COLUMN "logo_color" DROP DEFAULT; (params None)
[2025-04-19 09:05:35,239] DEBUG django.db.backends.schema: ALTER TABLE "admin_interface_theme" RENAME COLUMN "css_header_title_color" TO "title_color"; (params None)
[2025-04-19 09:05:35,244] DEBUG django.db.backends.schema: ALTER TABLE "admin_interface_theme" ADD COLUMN "recent_actions_visible" boolean DEFAULT true NOT NULL; (params None)
[2025-04-19 09:05:35,245] DEBUG django.db.backends.schema: ALTER TABLE "admin_interface_theme" ALTER COLUMN "recent_actions_visible" DROP DEFAULT; (params None)
[2025-04-19 09:05:35,305] DEBUG django.db.backends.schema: ALTER TABLE "admin_interface_theme" ADD COLUMN "favicon" varchar(100) DEFAULT '' NOT NULL; (params None)
[2025-04-19 09:05:35,307] DEBUG django.db.backends.schema: ALTER TABLE "admin_interface_theme" ALTER COLUMN "favicon" DROP DEFAULT; (params None)
[2025-04-19 09:05:35,311] DEBUG django.db.backends.schema: ALTER TABLE "admin_interface_theme" DROP COLUMN "related_modal_background_opacity" CASCADE; (params None)
[2025-04-19 09:05:35,314] DEBUG django.db.backends.schema: ALTER TABLE "admin_interface_theme" ADD COLUMN "related_modal_background_opacity" varchar(5) DEFAULT '0.3' NOT NULL; (params None)
[2025-04-19 09:05:35,315] DEBUG django.db.backends.schema: ALTER TABLE "admin_interface_theme" ALTER COLUMN "related_modal_background_opacity" DROP DEFAULT; (params None)
[2025-04-19 09:05:35,320] DEBUG django.db.backends.schema: ALTER TABLE "admin_interface_theme" ADD COLUMN "env" varchar(50) DEFAULT 'development' NOT NULL; (params None)
[2025-04-19 09:05:35,321] DEBUG django.db.backends.schema: ALTER TABLE "admin_interface_theme" ALTER COLUMN "env" DROP DEFAULT; (params None)
[2025-04-19 09:05:35,324] DEBUG django.db.backends.schema: ALTER TABLE "admin_interface_theme" ADD COLUMN "env_visible" boolean DEFAULT true NOT NULL; (params None)
[2025-04-19 09:05:35,325] DEBUG django.db.backends.schema: ALTER TABLE "admin_interface_theme" ALTER COLUMN "env_visible" DROP DEFAULT; (params None)
[2025-04-19 09:05:35,348] DEBUG django.db.backends.schema: ALTER TABLE "admin_interface_theme" RENAME COLUMN "env" TO "env_name"; (params None)
[2025-04-19 09:05:35,356] DEBUG django.db.backends.schema: ALTER TABLE "admin_interface_theme" ADD COLUMN "env_color" varchar(10) DEFAULT '#E74C3C' NOT NULL; (params None)
[2025-04-19 09:05:35,357] DEBUG django.db.backends.schema: ALTER TABLE "admin_interface_theme" ALTER COLUMN "env_color" DROP DEFAULT; (params None)
[2025-04-19 09:05:35,359] DEBUG django.db.backends.schema: ALTER TABLE "admin_interface_theme" RENAME COLUMN "env_visible" TO "env_visible_in_header"; (params None)
[2025-04-19 09:05:35,364] DEBUG django.db.backends.schema: ALTER TABLE "admin_interface_theme" ADD COLUMN "env_visible_in_favicon" boolean DEFAULT true NOT NULL; (params None)
[2025-04-19 09:05:35,365] DEBUG django.db.backends.schema: ALTER TABLE "admin_interface_theme" ALTER COLUMN "env_visible_in_favicon" DROP DEFAULT; (params None)
[2025-04-19 09:05:35,375] DEBUG django.db.backends.schema: ALTER TABLE "admin_interface_theme" ADD COLUMN "related_modal_close_button_visible" boolean DEFAULT true NOT NULL; (params None)
[2025-04-19 09:05:35,376] DEBUG django.db.backends.schema: ALTER TABLE "admin_interface_theme" ALTER COLUMN "related_modal_close_button_visible" DROP DEFAULT; (params None)
[2025-04-19 09:05:35,380] DEBUG django.db.backends.schema: ALTER TABLE "admin_interface_theme" ADD CONSTRAINT "admin_interface_theme_name_30bda70f_uniq" UNIQUE ("name"); (params None)
[2025-04-19 09:05:35,384] DEBUG django.db.backends.schema: CREATE INDEX "admin_interface_theme_name_30bda70f_like" ON "admin_interface_theme" ("name" varchar_pattern_ops); (params None)
[2025-04-19 09:05:35,390] DEBUG django.db.backends.schema: ALTER TABLE "admin_interface_theme" ADD COLUMN "language_chooser_active" boolean DEFAULT true NOT NULL; (params None)
[2025-04-19 09:05:35,391] DEBUG django.db.backends.schema: ALTER TABLE "admin_interface_theme" ALTER COLUMN "language_chooser_active" DROP DEFAULT; (params None)
[2025-04-19 09:05:35,395] DEBUG django.db.backends.schema: ALTER TABLE "admin_interface_theme" ADD COLUMN "language_chooser_display" varchar(10) DEFAULT 'code' NOT NULL; (params None)
[2025-04-19 09:05:35,397] DEBUG django.db.backends.schema: ALTER TABLE "admin_interface_theme" ALTER COLUMN "language_chooser_display" DROP DEFAULT; (params None)
[2025-04-19 09:05:35,405] DEBUG django.db.backends.schema: ALTER TABLE "admin_interface_theme" ADD COLUMN "list_filter_sticky" boolean DEFAULT true NOT NULL; (params None)
[2025-04-19 09:05:35,406] DEBUG django.db.backends.schema: ALTER TABLE "admin_interface_theme" ALTER COLUMN "list_filter_sticky" DROP DEFAULT; (params None)
[2025-04-19 09:05:35,412] DEBUG django.db.backends.schema: ALTER TABLE "admin_interface_theme" ADD COLUMN "form_pagination_sticky" boolean DEFAULT false NOT NULL; (params None)
[2025-04-19 09:05:35,413] DEBUG django.db.backends.schema: ALTER TABLE "admin_interface_theme" ALTER COLUMN "form_pagination_sticky" DROP DEFAULT; (params None)
[2025-04-19 09:05:35,416] DEBUG django.db.backends.schema: ALTER TABLE "admin_interface_theme" ADD COLUMN "form_submit_sticky" boolean DEFAULT false NOT NULL; (params None)
[2025-04-19 09:05:35,416] DEBUG django.db.backends.schema: ALTER TABLE "admin_interface_theme" ALTER COLUMN "form_submit_sticky" DROP DEFAULT; (params None)
[2025-04-19 09:05:35,421] DEBUG django.db.backends.schema: ALTER TABLE "admin_interface_theme" ADD COLUMN "css_module_background_selected_color" varchar(10) DEFAULT '#FFFFCC' NOT NULL; (params None)
[2025-04-19 09:05:35,422] DEBUG django.db.backends.schema: ALTER TABLE "admin_interface_theme" ALTER COLUMN "css_module_background_selected_color" DROP DEFAULT; (params None)
[2025-04-19 09:05:35,425] DEBUG django.db.backends.schema: ALTER TABLE "admin_interface_theme" ADD COLUMN "css_module_link_selected_color" varchar(10) DEFAULT '#FFFFFF' NOT NULL; (params None)
[2025-04-19 09:05:35,426] DEBUG django.db.backends.schema: ALTER TABLE "admin_interface_theme" ALTER COLUMN "css_module_link_selected_color" DROP DEFAULT; (params None)
[2025-04-19 09:05:35,445] DEBUG django.db.backends.schema: ALTER TABLE "admin_interface_theme" ADD COLUMN "logo_max_height" smallint DEFAULT 100 NOT NULL CHECK ("logo_max_height" >= 0); (params None)
[2025-04-19 09:05:35,446] DEBUG django.db.backends.schema: ALTER TABLE "admin_interface_theme" ALTER COLUMN "logo_max_height" DROP DEFAULT; (params None)
[2025-04-19 09:05:35,449] DEBUG django.db.backends.schema: ALTER TABLE "admin_interface_theme" ADD COLUMN "logo_max_width" smallint DEFAULT 400 NOT NULL CHECK ("logo_max_width" >= 0); (params None)
[2025-04-19 09:05:35,450] DEBUG django.db.backends.schema: ALTER TABLE "admin_interface_theme" ALTER COLUMN "logo_max_width" DROP DEFAULT; (params None)
[2025-04-19 09:05:35,455] DEBUG django.db.backends.schema: ALTER TABLE "admin_interface_theme" ADD COLUMN "foldable_apps" boolean DEFAULT true NOT NULL; (params None)
[2025-04-19 09:05:35,456] DEBUG django.db.backends.schema: ALTER TABLE "admin_interface_theme" ALTER COLUMN "foldable_apps" DROP DEFAULT; (params None)
[2025-04-19 09:05:35,463] DEBUG django.db.backends.schema: ALTER TABLE "admin_interface_theme" DROP COLUMN "css" CASCADE; (params None)
[2025-04-19 09:05:35,468] DEBUG django.db.backends.schema: ALTER TABLE "admin_interface_theme" ADD COLUMN "language_chooser_control" varchar(20) DEFAULT 'default-select' NOT NULL; (params None)
[2025-04-19 09:05:35,469] DEBUG django.db.backends.schema: ALTER TABLE "admin_interface_theme" ALTER COLUMN "language_chooser_control" DROP DEFAULT; (params None)
[2025-04-19 09:05:35,473] DEBUG django.db.backends.schema: ALTER TABLE "admin_interface_theme" ADD COLUMN "list_filter_highlight" boolean DEFAULT true NOT NULL; (params None)
[2025-04-19 09:05:35,474] DEBUG django.db.backends.schema: ALTER TABLE "admin_interface_theme" ALTER COLUMN "list_filter_highlight" DROP DEFAULT; (params None)
[2025-04-19 09:05:35,479] DEBUG django.db.backends.schema: ALTER TABLE "admin_interface_theme" ADD COLUMN "list_filter_removal_links" boolean DEFAULT false NOT NULL; (params None)
[2025-04-19 09:05:35,480] DEBUG django.db.backends.schema: ALTER TABLE "admin_interface_theme" ALTER COLUMN "list_filter_removal_links" DROP DEFAULT; (params None)
[2025-04-19 09:05:35,484] DEBUG django.db.backends.schema: ALTER TABLE "admin_interface_theme" ADD COLUMN "show_fieldsets_as_tabs" boolean DEFAULT false NOT NULL; (params None)
[2025-04-19 09:05:35,486] DEBUG django.db.backends.schema: ALTER TABLE "admin_interface_theme" ALTER COLUMN "show_fieldsets_as_tabs" DROP DEFAULT; (params None)
[2025-04-19 09:05:35,489] DEBUG django.db.backends.schema: ALTER TABLE "admin_interface_theme" ADD COLUMN "show_inlines_as_tabs" boolean DEFAULT false NOT NULL; (params None)
[2025-04-19 09:05:35,490] DEBUG django.db.backends.schema: ALTER TABLE "admin_interface_theme" ALTER COLUMN "show_inlines_as_tabs" DROP DEFAULT; (params None)
[2025-04-19 09:05:35,494] DEBUG django.db.backends.schema: ALTER TABLE "admin_interface_theme" ADD COLUMN "css_generic_link_active_color" varchar(10) DEFAULT '#29B864' NOT NULL; (params None)
[2025-04-19 09:05:35,496] DEBUG django.db.backends.schema: ALTER TABLE "admin_interface_theme" ALTER COLUMN "css_generic_link_active_color" DROP DEFAULT; (params None)
[2025-04-19 09:05:35,500] DEBUG django.db.backends.schema: ALTER TABLE "admin_interface_theme" ADD COLUMN "collapsible_stacked_inlines" boolean DEFAULT false NOT NULL; (params None)
[2025-04-19 09:05:35,501] DEBUG django.db.backends.schema: ALTER TABLE "admin_interface_theme" ALTER COLUMN "collapsible_stacked_inlines" DROP DEFAULT; (params None)
[2025-04-19 09:05:35,505] DEBUG django.db.backends.schema: ALTER TABLE "admin_interface_theme" ADD COLUMN "collapsible_stacked_inlines_collapsed" boolean DEFAULT true NOT NULL; (params None)
[2025-04-19 09:05:35,505] DEBUG django.db.backends.schema: ALTER TABLE "admin_interface_theme" ALTER COLUMN "collapsible_stacked_inlines_collapsed" DROP DEFAULT; (params None)
[2025-04-19 09:05:35,509] DEBUG django.db.backends.schema: ALTER TABLE "admin_interface_theme" ADD COLUMN "collapsible_tabular_inlines" boolean DEFAULT false NOT NULL; (params None)
[2025-04-19 09:05:35,509] DEBUG django.db.backends.schema: ALTER TABLE "admin_interface_theme" ALTER COLUMN "collapsible_tabular_inlines" DROP DEFAULT; (params None)
[2025-04-19 09:05:35,513] DEBUG django.db.backends.schema: ALTER TABLE "admin_interface_theme" ADD COLUMN "collapsible_tabular_inlines_collapsed" boolean DEFAULT true NOT NULL; (params None)
[2025-04-19 09:05:35,513] DEBUG django.db.backends.schema: ALTER TABLE "admin_interface_theme" ALTER COLUMN "collapsible_tabular_inlines_collapsed" DROP DEFAULT; (params None)
[2025-04-19 09:05:35,516] DEBUG django.db.backends.schema: CREATE TABLE "django_session" ("session_key" varchar(40) NOT NULL PRIMARY KEY, "session_data" text NOT NULL, "expire_date" timestamp with time zone NOT NULL); (params None)
[2025-04-19 09:05:35,522] DEBUG django.db.backends.schema: CREATE INDEX "django_session_session_key_c0390e0f_like" ON "django_session" ("session_key" varchar_pattern_ops); (params None)
[2025-04-19 09:05:35,524] DEBUG django.db.backends.schema: CREATE INDEX "django_session_expire_date_a5c62663" ON "django_session" ("expire_date"); (params None)
[2025-04-19 09:05:35,530] DEBUG django.db.backends.schema: CREATE TABLE "shop_category" ("id" bigint NOT NULL PRIMARY KEY GENERATED BY DEFAULT AS IDENTITY, "name" varchar(100) NOT NULL, "description" text NULL); (params None)
[2025-04-19 09:05:35,538] DEBUG django.db.backends.schema: CREATE TABLE "shop_product" ("id" bigint NOT NULL PRIMARY KEY GENERATED BY DEFAULT AS IDENTITY, "name" varchar(100) NOT NULL, "description" text NOT NULL, "price" numeric(10, 2) NOT NULL, "image" varchar(100) NULL, "quantity" integer NOT NULL CHECK ("quantity" >= 0), "category_id" bigint NOT NULL); (params None)
[2025-04-19 09:05:35,544] DEBUG django.db.backends.schema: ALTER TABLE "shop_product" ADD CONSTRAINT "shop_product_category_id_14d7eea8_fk_shop_category_id" FOREIGN KEY ("category_id") REFERENCES "shop_category" ("id") DEFERRABLE INITIALLY DEFERRED; (params None)
[2025-04-19 09:05:35,546] DEBUG django.db.backends.schema: CREATE INDEX "shop_product_category_id_14d7eea8" ON "shop_product" ("category_id"); (params None)
[2025-04-19 09:05:35,557] DEBUG django.db.backends.schema: CREATE TABLE "shop_basket" ("id" bigint NOT NULL PRIMARY KEY GENERATED BY DEFAULT AS IDENTITY, "quantity" integer NOT NULL CHECK ("quantity" >= 0), "product_id" bigint NOT NULL, "user_id" bigint NOT NULL); (params None)
[2025-04-19 09:05:35,561] DEBUG django.db.backends.schema: ALTER TABLE "shop_basket" ADD CONSTRAINT "shop_basket_product_id_4ac649ff_fk_shop_product_id" FOREIGN KEY ("product_id") REFERENCES "shop_product" ("id") DEFERRABLE INITIALLY DEFERRED; (params None)
[2025-04-19 09:05:35,562] DEBUG django.db.backends.schema: ALTER TABLE "shop_basket" ADD CONSTRAINT "shop_basket_user_id_0cdbdfcb_fk_user_customuser_id" FOREIGN KEY ("user_id") REFERENCES "user_customuser" ("id") DEFERRABLE INITIALLY DEFERRED; (params None)
[2025-04-19 09:05:35,563] DEBUG django.db.backends.schema: CREATE INDEX "shop_basket_product_id_4ac649ff" ON "shop_basket" ("product_id"); (params None)
[2025-04-19 09:05:35,566] DEBUG django.db.backends.schema: CREATE INDEX "shop_basket_user_id_0cdbdfcb" ON "shop_basket" ("user_id"); (params None)
[2025-04-19 09:05:35,572] DEBUG django.db.backends.schema: ALTER TABLE "shop_product" ADD COLUMN "created_at" timestamp with time zone DEFAULT '2025-04-19 09:05:35.572503+00:00'::timestamptz NOT NULL; (params None)
[2025-04-19 09:05:35,573] DEBUG django.db.backends.schema: ALTER TABLE "shop_product" ALTER COLUMN "created_at" DROP DEFAULT; (params None)
[2025-04-19 09:05:35,584] DEBUG django.db.backends.schema: CREATE TABLE "token_blacklist_blacklistedtoken" ("id" integer NOT NULL PRIMARY KEY GENERATED BY DEFAULT AS IDENTITY, "blacklisted_at" timestamp with time zone NOT NULL); (params None)
[2025-04-19 09:05:35,597] DEBUG django.db.backends.schema: CREATE TABLE "token_blacklist_outstandingtoken" ("id" integer NOT NULL PRIMARY KEY GENERATED BY DEFAULT AS IDENTITY, "jti" uuid NOT NULL UNIQUE, "token" text NOT NULL, "created_at" timestamp with time zone NOT NULL, "expires_at" timestamp with time zone NOT NULL, "user_id" bigint NOT NULL); (params None)
[2025-04-19 09:05:35,612] DEBUG django.db.backends.schema: ALTER TABLE "token_blacklist_blacklistedtoken" ADD COLUMN "token_id" integer NOT NULL UNIQUE CONSTRAINT "token_blacklist_blac_token_id_3cc7fe56_fk_token_bla" REFERENCES "token_blacklist_outstandingtoken"("id") DEFERRABLE INITIALLY DEFERRED; SET CONSTRAINTS "token_blacklist_blac_token_id_3cc7fe56_fk_token_bla" IMMEDIATE; (params None)
[2025-04-19 09:05:35,615] DEBUG django.db.backends.schema: ALTER TABLE "token_blacklist_outstandingtoken" ADD CONSTRAINT "token_blacklist_outs_user_id_83bc629a_fk_user_cust" FOREIGN KEY ("user_id") REFERENCES "user_customuser" ("id") DEFERRABLE INITIALLY DEFERRED; (params None)
[2025-04-19 09:05:35,616] DEBUG django.db.backends.schema: CREATE INDEX "token_blacklist_outstandingtoken_user_id_83bc629a" ON "token_blacklist_outstandingtoken" ("user_id"); (params None)
[2025-04-19 09:05:35,627] DEBUG django.db.backends.schema: ALTER TABLE "token_blacklist_outstandingtoken" ADD COLUMN "jti_hex" varchar(255) NULL; (params None)
[2025-04-19 09:05:35,649] DEBUG django.db.backends.schema: ALTER TABLE "token_blacklist_outstandingtoken" ALTER COLUMN "jti_hex" SET NOT NULL; (params None)
[2025-04-19 09:05:35,650] DEBUG django.db.backends.schema: ALTER TABLE "token_blacklist_outstandingtoken" ADD CONSTRAINT "token_blacklist_outstandingtoken_jti_hex_d9bdf6f7_uniq" UNIQUE ("jti_hex"); (params None)
[2025-04-19 09:05:35,653] DEBUG django.db.backends.schema: CREATE INDEX "token_blacklist_outstandingtoken_jti_hex_d9bdf6f7_like" ON "token_blacklist_outstandingtoken" ("jti_hex" varchar_pattern_ops); (params None)
[2025-04-19 09:05:35,662] DEBUG django.db.backends.schema: ALTER TABLE "token_blacklist_outstandingtoken" DROP COLUMN "jti" CASCADE; (params None)
[2025-04-19 09:05:35,672] DEBUG django.db.backends.schema: ALTER TABLE "token_blacklist_outstandingtoken" RENAME COLUMN "jti_hex" TO "jti"; (params None)
[2025-04-19 09:05:35,683] DEBUG django.db.backends.schema: ALTER TABLE "token_blacklist_outstandingtoken" ALTER COLUMN "created_at" DROP NOT NULL; (params None)
[2025-04-19 09:05:35,696] DEBUG django.db.backends.schema: SET CONSTRAINTS "token_blacklist_outs_user_id_83bc629a_fk_user_cust" IMMEDIATE; ALTER TABLE "token_blacklist_outstandingtoken" DROP CONSTRAINT "token_blacklist_outs_user_id_83bc629a_fk_user_cust"; (params None)
[2025-04-19 09:05:35,697] DEBUG django.db.backends.schema: ALTER TABLE "token_blacklist_outstandingtoken" ALTER COLUMN "user_id" DROP NOT NULL; (params None)
[2025-04-19 09:05:35,697] DEBUG django.db.backends.schema: ALTER TABLE "token_blacklist_outstandingtoken" ADD CONSTRAINT "token_blacklist_outs_user_id_83bc629a_fk_user_cust" FOREIGN KEY ("user_id") REFERENCES "user_customuser" ("id") DEFERRABLE INITIALLY DEFERRED; (params None)
[2025-04-19 09:05:35,705] DEBUG django.db.backends.schema: ALTER TABLE "token_blacklist_blacklistedtoken" ALTER COLUMN "id" TYPE bigint USING "id"::bigint; (params None)
[2025-04-19 09:05:35,711] DEBUG django.db.backends.schema: ALTER SEQUENCE IF EXISTS "token_blacklist_blacklistedtoken_id_seq" AS bigint; (params None)
[2025-04-19 09:05:35,724] DEBUG django.db.backends.schema: SET CONSTRAINTS "token_blacklist_blac_token_id_3cc7fe56_fk_token_bla" IMMEDIATE; ALTER TABLE "token_blacklist_blacklistedtoken" DROP CONSTRAINT "token_blacklist_blac_token_id_3cc7fe56_fk_token_bla"; (params None)
[2025-04-19 09:05:35,725] DEBUG django.db.backends.schema: ALTER TABLE "token_blacklist_outstandingtoken" ALTER COLUMN "id" TYPE bigint USING "id"::bigint; (params None)
[2025-04-19 09:05:35,735] DEBUG django.db.backends.schema: ALTER SEQUENCE IF EXISTS "token_blacklist_outstandingtoken_id_seq" AS bigint; (params None)
[2025-04-19 09:05:35,736] DEBUG django.db.backends.schema: ALTER TABLE "token_blacklist_blacklistedtoken" ALTER COLUMN "token_id" TYPE bigint USING "token_id"::bigint; (params None)
[2025-04-19 09:05:35,741] DEBUG django.db.backends.schema: ALTER TABLE "token_blacklist_blacklistedtoken" ADD CONSTRAINT "token_blacklist_blacklistedtoken_token_id_3cc7fe56_fk" FOREIGN KEY ("token_id") REFERENCES "token_blacklist_outstandingtoken" ("id") DEFERRABLE INITIALLY DEFERRED; (params None)
[2025-04-19 09:05:35,779] DEBUG django.db.backends.schema: ALTER TABLE "user_customuser" DROP CONSTRAINT "user_customuser_username_key"; (params None)
[2025-04-19 09:05:35,779] DEBUG django.db.backends.schema: ALTER TABLE "user_customuser" ALTER COLUMN "username" TYPE varchar(30); (params None)
[2025-04-19 09:05:35,789] DEBUG django.db.backends.schema: DROP INDEX IF EXISTS "user_customuser_username_24be6f7e_like"; (params None)
[2025-04-19 09:05:35,798] DEBUG django.db.backends.schema: ALTER TABLE "user_customuser" ADD COLUMN "is_email_verified" boolean DEFAULT false NOT NULL; (params None)
[2025-04-19 09:05:35,799] DEBUG django.db.backends.schema: ALTER TABLE "user_customuser" ALTER COLUMN "is_email_verified" DROP DEFAULT; (params None)
[2025-04-19 09:05:37,148] INFO user.email_services: Попытка подтвердить email с uidb64 Mw
[2025-04-19 09:05:37,150] INFO user.email_services: Пользователь найден для uidb64 Mw: user_id 3
[2025-04-19 09:05:37,164] ERROR django.request: Internal Server Error: /api/verify-email/Mw/coi19d-9c11c1bea12245e95354d90e5e06c0a1/
Traceback (most recent call last):
  File "/usr/local/lib/python3.12/site-packages/django_redis/cache.py", line 29, in _decorator
    return method(self, *args, **kwargs)
           ^^^^^^^^^^^^^^^^^^^^^^^^^^^^^
  File "/usr/local/lib/python3.12/site-packages/django_redis/cache.py", line 99, in _get
    return self.client.get(key, default=default, version=version, client=client)
           ^^^^^^^^^^^^^^^^^^^^^^^^^^^^^^^^^^^^^^^^^^^^^^^^^^^^^^^^^^^^^^^^^^^^^
  File "/usr/local/lib/python3.12/site-packages/django_redis/client/default.py", line 260, in get
    raise ConnectionInterrupted(connection=client) from e
django_redis.exceptions.ConnectionInterrupted: Redis ConnectionError: Error 111 connecting to localhost:6379. Connection refused.

During handling of the above exception, another exception occurred:

Traceback (most recent call last):
  File "/usr/local/lib/python3.12/site-packages/django/core/handlers/exception.py", line 55, in inner
    response = get_response(request)
               ^^^^^^^^^^^^^^^^^^^^^
  File "/usr/local/lib/python3.12/site-packages/django/core/handlers/base.py", line 197, in _get_response
    response = wrapped_callback(request, *callback_args, **callback_kwargs)
               ^^^^^^^^^^^^^^^^^^^^^^^^^^^^^^^^^^^^^^^^^^^^^^^^^^^^^^^^^^^^
  File "/usr/local/lib/python3.12/site-packages/django/views/decorators/csrf.py", line 65, in _view_wrapper
    return view_func(request, *args, **kwargs)
           ^^^^^^^^^^^^^^^^^^^^^^^^^^^^^^^^^^^
  File "/usr/local/lib/python3.12/site-packages/django/views/generic/base.py", line 104, in view
    return self.dispatch(request, *args, **kwargs)
           ^^^^^^^^^^^^^^^^^^^^^^^^^^^^^^^^^^^^^^^
  File "/usr/local/lib/python3.12/site-packages/rest_framework/views.py", line 509, in dispatch
    response = self.handle_exception(exc)
               ^^^^^^^^^^^^^^^^^^^^^^^^^^
  File "/usr/local/lib/python3.12/site-packages/rest_framework/views.py", line 469, in handle_exception
    self.raise_uncaught_exception(exc)
  File "/usr/local/lib/python3.12/site-packages/rest_framework/views.py", line 480, in raise_uncaught_exception
    raise exc
  File "/usr/local/lib/python3.12/site-packages/rest_framework/views.py", line 506, in dispatch
    response = handler(request, *args, **kwargs)
               ^^^^^^^^^^^^^^^^^^^^^^^^^^^^^^^^^
  File "/backend/user/email_services.py", line 72, in get
    if default_token_generator.check_token(user, token) and cache.get(f"email_token_{user.id}") == token:
                                                            ^^^^^^^^^^^^^^^^^^^^^^^^^^^^^^^^^^^
  File "/usr/local/lib/python3.12/site-packages/django_redis/cache.py", line 92, in get
    value = self._get(key, default, version, client)
            ^^^^^^^^^^^^^^^^^^^^^^^^^^^^^^^^^^^^^^^^
  File "/usr/local/lib/python3.12/site-packages/django_redis/cache.py", line 36, in _decorator
    raise e.__cause__
  File "/usr/local/lib/python3.12/site-packages/django_redis/client/default.py", line 258, in get
    value = client.get(key)
            ^^^^^^^^^^^^^^^
  File "/usr/local/lib/python3.12/site-packages/redis/commands/core.py", line 1822, in get
    return self.execute_command("GET", name, keys=[name])
           ^^^^^^^^^^^^^^^^^^^^^^^^^^^^^^^^^^^^^^^^^^^^^^
  File "/usr/local/lib/python3.12/site-packages/redis/client.py", line 559, in execute_command
    return self._execute_command(*args, **options)
           ^^^^^^^^^^^^^^^^^^^^^^^^^^^^^^^^^^^^^^^
  File "/usr/local/lib/python3.12/site-packages/redis/client.py", line 565, in _execute_command
    conn = self.connection or pool.get_connection(command_name, **options)
                              ^^^^^^^^^^^^^^^^^^^^^^^^^^^^^^^^^^^^^^^^^^^^
  File "/usr/local/lib/python3.12/site-packages/redis/connection.py", line 1422, in get_connection
    connection.connect()
  File "/usr/local/lib/python3.12/site-packages/redis/connection.py", line 363, in connect
    raise ConnectionError(self._error_message(e))
redis.exceptions.ConnectionError: Error 111 connecting to localhost:6379. Connection refused.
[2025-04-19 09:05:37,475] INFO user.views: Попытка входа: test@example.com
[2025-04-19 09:05:37,638] INFO user.views: Успешный вход: test@example.com
[2025-04-19 09:05:37,797] INFO user.views: Попытка входа: test@example.com
[2025-04-19 09:05:37,954] WARNING django.request: Bad Request: /api/auth/login/
[2025-04-19 09:05:38,114] INFO user.views: Попытка входа: invalid_email@example.com
[2025-04-19 09:05:38,115] WARNING django.request: Bad Request: /api/auth/login/
[2025-04-19 09:05:38,273] INFO user.views: Попытка входа: test@example.com
[2025-04-19 09:05:38,430] WARNING django.request: Bad Request: /api/auth/login/
[2025-04-19 09:05:38,589] INFO user.views: Попытка входа: test@example.com
[2025-04-19 09:05:38,741] INFO user.views: Успешный вход: test@example.com
[2025-04-19 09:05:38,743] INFO user.views: Пользователь test@example.com выходит из системы
[2025-04-19 09:05:38,748] INFO user.views: Пользователь test@example.com успешно вышел
[2025-04-19 09:05:38,915] INFO user.views: Попытка входа: test@example.com
[2025-04-19 09:05:39,069] INFO user.views: Успешный вход: test@example.com
[2025-04-19 09:05:39,071] WARNING django.request: Unauthorized: /api/auth/logout/
[2025-04-19 09:05:39,230] INFO user.views: Попытка входа: test@example.com
[2025-04-19 09:05:39,389] INFO user.views: Успешный вход: test@example.com
[2025-04-19 09:05:39,391] INFO user.views: Пользователь test@example.com выходит из системы
[2025-04-19 09:05:39,392] WARNING django.request: Bad Request: /api/auth/logout/
[2025-04-19 09:05:39,567] ERROR django.request: Internal Server Error: /api/auth/reset-password/
Traceback (most recent call last):
  File "/usr/local/lib/python3.12/site-packages/django_redis/cache.py", line 29, in _decorator
    return method(self, *args, **kwargs)
           ^^^^^^^^^^^^^^^^^^^^^^^^^^^^^
  File "/usr/local/lib/python3.12/site-packages/django_redis/cache.py", line 81, in set
    return self.client.set(*args, **kwargs)
           ^^^^^^^^^^^^^^^^^^^^^^^^^^^^^^^^
  File "/usr/local/lib/python3.12/site-packages/django_redis/client/default.py", line 185, in set
    raise ConnectionInterrupted(connection=client) from e
django_redis.exceptions.ConnectionInterrupted: Redis ConnectionError: Error 111 connecting to localhost:6379. Connection refused.

During handling of the above exception, another exception occurred:

Traceback (most recent call last):
  File "/usr/local/lib/python3.12/site-packages/django/core/handlers/exception.py", line 55, in inner
    response = get_response(request)
               ^^^^^^^^^^^^^^^^^^^^^
  File "/usr/local/lib/python3.12/site-packages/django/core/handlers/base.py", line 197, in _get_response
    response = wrapped_callback(request, *callback_args, **callback_kwargs)
               ^^^^^^^^^^^^^^^^^^^^^^^^^^^^^^^^^^^^^^^^^^^^^^^^^^^^^^^^^^^^
  File "/usr/local/lib/python3.12/site-packages/django/views/decorators/csrf.py", line 65, in _view_wrapper
    return view_func(request, *args, **kwargs)
           ^^^^^^^^^^^^^^^^^^^^^^^^^^^^^^^^^^^
  File "/usr/local/lib/python3.12/site-packages/django/views/generic/base.py", line 104, in view
    return self.dispatch(request, *args, **kwargs)
           ^^^^^^^^^^^^^^^^^^^^^^^^^^^^^^^^^^^^^^^
  File "/usr/local/lib/python3.12/site-packages/rest_framework/views.py", line 509, in dispatch
    response = self.handle_exception(exc)
               ^^^^^^^^^^^^^^^^^^^^^^^^^^
  File "/usr/local/lib/python3.12/site-packages/rest_framework/views.py", line 469, in handle_exception
    self.raise_uncaught_exception(exc)
  File "/usr/local/lib/python3.12/site-packages/rest_framework/views.py", line 480, in raise_uncaught_exception
    raise exc
  File "/usr/local/lib/python3.12/site-packages/rest_framework/views.py", line 506, in dispatch
    response = handler(request, *args, **kwargs)
               ^^^^^^^^^^^^^^^^^^^^^^^^^^^^^^^^^
  File "/backend/user/views.py", line 136, in post
    cache.set(cache_key, token, timeout=3600)
  File "/usr/local/lib/python3.12/site-packages/django_redis/cache.py", line 36, in _decorator
    raise e.__cause__
  File "/usr/local/lib/python3.12/site-packages/django_redis/client/default.py", line 175, in set
    return bool(client.set(nkey, nvalue, nx=nx, px=timeout, xx=xx))
                ^^^^^^^^^^^^^^^^^^^^^^^^^^^^^^^^^^^^^^^^^^^^^^^^^^
  File "/usr/local/lib/python3.12/site-packages/redis/commands/core.py", line 2335, in set
    return self.execute_command("SET", *pieces, **options)
           ^^^^^^^^^^^^^^^^^^^^^^^^^^^^^^^^^^^^^^^^^^^^^^^
  File "/usr/local/lib/python3.12/site-packages/redis/client.py", line 559, in execute_command
    return self._execute_command(*args, **options)
           ^^^^^^^^^^^^^^^^^^^^^^^^^^^^^^^^^^^^^^^
  File "/usr/local/lib/python3.12/site-packages/redis/client.py", line 565, in _execute_command
    conn = self.connection or pool.get_connection(command_name, **options)
                              ^^^^^^^^^^^^^^^^^^^^^^^^^^^^^^^^^^^^^^^^^^^^
  File "/usr/local/lib/python3.12/site-packages/redis/connection.py", line 1422, in get_connection
    connection.connect()
  File "/usr/local/lib/python3.12/site-packages/redis/connection.py", line 363, in connect
    raise ConnectionError(self._error_message(e))
redis.exceptions.ConnectionError: Error 111 connecting to localhost:6379. Connection refused.
[2025-04-19 09:05:39,717] WARNING user.views: Запрос восстановления пароля без email
[2025-04-19 09:05:39,719] WARNING django.request: Bad Request: /api/auth/reset-password/
[2025-04-19 09:05:39,723] WARNING user.views: Пользователь не найден при попытке восстановления пароля: unknown@example.com
[2025-04-19 09:05:39,724] WARNING django.request: Bad Request: /api/auth/reset-password/
[2025-04-19 09:05:39,972] INFO user.views: Запрос на подтверждение смены пароля
[2025-04-19 09:05:39,972] ERROR user.views: Ошибка при декодировании или поиске пользователя: 'utf-8' codec can't decode byte 0x8a in position 0: invalid start byte
[2025-04-19 09:05:39,973] WARNING django.request: Bad Request: /api/auth/reset-password/invalid/token/
[2025-04-19 09:05:40,150] INFO user.views: Запрос на подтверждение смены пароля
[2025-04-19 09:05:40,151] WARNING user.views: Невалидный или истёкший токен для пользователя test@example.com
[2025-04-19 09:05:40,152] WARNING django.request: Bad Request: /api/auth/reset-password/MTM/badtoken/
[2025-04-19 09:05:40,309] INFO user.views: Запрос на подтверждение смены пароля
[2025-04-19 09:05:40,311] ERROR django.request: Internal Server Error: /api/auth/reset-password/MTQ/coi19g-b5e48efa6f1e1cdc5ce0dab8e97dd54a/
Traceback (most recent call last):
  File "/usr/local/lib/python3.12/site-packages/django_redis/cache.py", line 29, in _decorator
    return method(self, *args, **kwargs)
           ^^^^^^^^^^^^^^^^^^^^^^^^^^^^^
  File "/usr/local/lib/python3.12/site-packages/django_redis/cache.py", line 99, in _get
    return self.client.get(key, default=default, version=version, client=client)
           ^^^^^^^^^^^^^^^^^^^^^^^^^^^^^^^^^^^^^^^^^^^^^^^^^^^^^^^^^^^^^^^^^^^^^
  File "/usr/local/lib/python3.12/site-packages/django_redis/client/default.py", line 260, in get
    raise ConnectionInterrupted(connection=client) from e
django_redis.exceptions.ConnectionInterrupted: Redis ConnectionError: Error 111 connecting to localhost:6379. Connection refused.

During handling of the above exception, another exception occurred:

Traceback (most recent call last):
  File "/usr/local/lib/python3.12/site-packages/django/core/handlers/exception.py", line 55, in inner
    response = get_response(request)
               ^^^^^^^^^^^^^^^^^^^^^
  File "/usr/local/lib/python3.12/site-packages/django/core/handlers/base.py", line 197, in _get_response
    response = wrapped_callback(request, *callback_args, **callback_kwargs)
               ^^^^^^^^^^^^^^^^^^^^^^^^^^^^^^^^^^^^^^^^^^^^^^^^^^^^^^^^^^^^
  File "/usr/local/lib/python3.12/site-packages/django/views/decorators/csrf.py", line 65, in _view_wrapper
    return view_func(request, *args, **kwargs)
           ^^^^^^^^^^^^^^^^^^^^^^^^^^^^^^^^^^^
  File "/usr/local/lib/python3.12/site-packages/django/views/generic/base.py", line 104, in view
    return self.dispatch(request, *args, **kwargs)
           ^^^^^^^^^^^^^^^^^^^^^^^^^^^^^^^^^^^^^^^
  File "/usr/local/lib/python3.12/site-packages/rest_framework/views.py", line 509, in dispatch
    response = self.handle_exception(exc)
               ^^^^^^^^^^^^^^^^^^^^^^^^^^
  File "/usr/local/lib/python3.12/site-packages/rest_framework/views.py", line 469, in handle_exception
    self.raise_uncaught_exception(exc)
  File "/usr/local/lib/python3.12/site-packages/rest_framework/views.py", line 480, in raise_uncaught_exception
    raise exc
  File "/usr/local/lib/python3.12/site-packages/rest_framework/views.py", line 506, in dispatch
    response = handler(request, *args, **kwargs)
               ^^^^^^^^^^^^^^^^^^^^^^^^^^^^^^^^^
  File "/backend/user/views.py", line 166, in post
    if not default_token_generator.check_token(user, token) or cache.get(f"reset_password_{user.id}") != token:
                                                               ^^^^^^^^^^^^^^^^^^^^^^^^^^^^^^^^^^^^^^
  File "/usr/local/lib/python3.12/site-packages/django_redis/cache.py", line 92, in get
    value = self._get(key, default, version, client)
            ^^^^^^^^^^^^^^^^^^^^^^^^^^^^^^^^^^^^^^^^
  File "/usr/local/lib/python3.12/site-packages/django_redis/cache.py", line 36, in _decorator
    raise e.__cause__
  File "/usr/local/lib/python3.12/site-packages/django_redis/client/default.py", line 258, in get
    value = client.get(key)
            ^^^^^^^^^^^^^^^
  File "/usr/local/lib/python3.12/site-packages/redis/commands/core.py", line 1822, in get
    return self.execute_command("GET", name, keys=[name])
           ^^^^^^^^^^^^^^^^^^^^^^^^^^^^^^^^^^^^^^^^^^^^^^
  File "/usr/local/lib/python3.12/site-packages/redis/client.py", line 559, in execute_command
    return self._execute_command(*args, **options)
           ^^^^^^^^^^^^^^^^^^^^^^^^^^^^^^^^^^^^^^^
  File "/usr/local/lib/python3.12/site-packages/redis/client.py", line 565, in _execute_command
    conn = self.connection or pool.get_connection(command_name, **options)
                              ^^^^^^^^^^^^^^^^^^^^^^^^^^^^^^^^^^^^^^^^^^^^
  File "/usr/local/lib/python3.12/site-packages/redis/connection.py", line 1422, in get_connection
    connection.connect()
  File "/usr/local/lib/python3.12/site-packages/redis/connection.py", line 363, in connect
    raise ConnectionError(self._error_message(e))
redis.exceptions.ConnectionError: Error 111 connecting to localhost:6379. Connection refused.
[2025-04-19 09:05:40,905] INFO user.views: Успешная регистрация пользователя: test@example.com
[2025-04-19 09:05:41,069] WARNING django.request: Bad Request: /api/auth/register/
[2025-04-19 09:05:41,074] WARNING django.request: Bad Request: /api/auth/register/
[2025-04-19 09:05:41,077] WARNING django.request: Bad Request: /api/auth/register/
[2025-04-19 09:05:41,081] WARNING django.request: Bad Request: /api/auth/register/
[2025-04-19 09:05:41,085] WARNING django.request: Bad Request: /api/auth/register/
[2025-04-19 09:05:41,091] WARNING django.request: Bad Request: /api/auth/register/
[2025-04-19 09:05:41,249] INFO user.views: Попытка входа: test@example.com
[2025-04-19 09:05:41,426] INFO user.views: Успешный вход: test@example.com
[2025-04-19 09:05:41,429] INFO shop.views: Просмотр корзины для пользователя с ID 18
[2025-04-19 09:05:41,429] INFO shop.utils.cache: Сформирован ключ кеша: basket_00477aae99967c299f6df11039726b2d
[2025-04-19 09:05:41,430] ERROR django.request: Internal Server Error: /api/shop/basket/
Traceback (most recent call last):
  File "/usr/local/lib/python3.12/site-packages/django_redis/cache.py", line 29, in _decorator
    return method(self, *args, **kwargs)
           ^^^^^^^^^^^^^^^^^^^^^^^^^^^^^
  File "/usr/local/lib/python3.12/site-packages/django_redis/cache.py", line 99, in _get
    return self.client.get(key, default=default, version=version, client=client)
           ^^^^^^^^^^^^^^^^^^^^^^^^^^^^^^^^^^^^^^^^^^^^^^^^^^^^^^^^^^^^^^^^^^^^^
  File "/usr/local/lib/python3.12/site-packages/django_redis/client/default.py", line 260, in get
    raise ConnectionInterrupted(connection=client) from e
django_redis.exceptions.ConnectionInterrupted: Redis ConnectionError: Error 111 connecting to localhost:6379. Connection refused.

During handling of the above exception, another exception occurred:

Traceback (most recent call last):
  File "/usr/local/lib/python3.12/site-packages/django/core/handlers/exception.py", line 55, in inner
    response = get_response(request)
               ^^^^^^^^^^^^^^^^^^^^^
  File "/usr/local/lib/python3.12/site-packages/django/core/handlers/base.py", line 197, in _get_response
    response = wrapped_callback(request, *callback_args, **callback_kwargs)
               ^^^^^^^^^^^^^^^^^^^^^^^^^^^^^^^^^^^^^^^^^^^^^^^^^^^^^^^^^^^^
  File "/usr/local/lib/python3.12/site-packages/django/views/decorators/csrf.py", line 65, in _view_wrapper
    return view_func(request, *args, **kwargs)
           ^^^^^^^^^^^^^^^^^^^^^^^^^^^^^^^^^^^
  File "/usr/local/lib/python3.12/site-packages/django/views/generic/base.py", line 104, in view
    return self.dispatch(request, *args, **kwargs)
           ^^^^^^^^^^^^^^^^^^^^^^^^^^^^^^^^^^^^^^^
  File "/usr/local/lib/python3.12/site-packages/rest_framework/views.py", line 509, in dispatch
    response = self.handle_exception(exc)
               ^^^^^^^^^^^^^^^^^^^^^^^^^^
  File "/usr/local/lib/python3.12/site-packages/rest_framework/views.py", line 469, in handle_exception
    self.raise_uncaught_exception(exc)
  File "/usr/local/lib/python3.12/site-packages/rest_framework/views.py", line 480, in raise_uncaught_exception
    raise exc
  File "/usr/local/lib/python3.12/site-packages/rest_framework/views.py", line 506, in dispatch
    response = handler(request, *args, **kwargs)
               ^^^^^^^^^^^^^^^^^^^^^^^^^^^^^^^^^
  File "/backend/shop/views.py", line 132, in get
    return get_cached_list_response(
           ^^^^^^^^^^^^^^^^^^^^^^^^^
  File "/backend/shop/utils/cache.py", line 27, in get_cached_list_response
    cached_data = cache.get(cache_key)
                  ^^^^^^^^^^^^^^^^^^^^
  File "/usr/local/lib/python3.12/site-packages/django_redis/cache.py", line 92, in get
    value = self._get(key, default, version, client)
            ^^^^^^^^^^^^^^^^^^^^^^^^^^^^^^^^^^^^^^^^
  File "/usr/local/lib/python3.12/site-packages/django_redis/cache.py", line 36, in _decorator
    raise e.__cause__
  File "/usr/local/lib/python3.12/site-packages/django_redis/client/default.py", line 258, in get
    value = client.get(key)
            ^^^^^^^^^^^^^^^
  File "/usr/local/lib/python3.12/site-packages/redis/commands/core.py", line 1822, in get
    return self.execute_command("GET", name, keys=[name])
           ^^^^^^^^^^^^^^^^^^^^^^^^^^^^^^^^^^^^^^^^^^^^^^
  File "/usr/local/lib/python3.12/site-packages/redis/client.py", line 559, in execute_command
    return self._execute_command(*args, **options)
           ^^^^^^^^^^^^^^^^^^^^^^^^^^^^^^^^^^^^^^^
  File "/usr/local/lib/python3.12/site-packages/redis/client.py", line 565, in _execute_command
    conn = self.connection or pool.get_connection(command_name, **options)
                              ^^^^^^^^^^^^^^^^^^^^^^^^^^^^^^^^^^^^^^^^^^^^
  File "/usr/local/lib/python3.12/site-packages/redis/connection.py", line 1422, in get_connection
    connection.connect()
  File "/usr/local/lib/python3.12/site-packages/redis/connection.py", line 363, in connect
    raise ConnectionError(self._error_message(e))
redis.exceptions.ConnectionError: Error 111 connecting to localhost:6379. Connection refused.
[2025-04-19 09:05:41,719] INFO user.views: Попытка входа: test@example.com
[2025-04-19 09:05:41,888] INFO user.views: Успешный вход: test@example.com
[2025-04-19 09:05:41,890] WARNING django.request: Unauthorized: /api/shop/basket/
[2025-04-19 09:05:42,070] INFO user.views: Попытка входа: test@example.com
[2025-04-19 09:05:42,224] INFO user.views: Успешный вход: test@example.com
[2025-04-19 09:05:42,227] INFO shop.signals: Изменения или удаление категории с ID 1. Очистка кеша категорий.
[2025-04-19 09:05:42,529] INFO user.views: Попытка входа: test@example.com
[2025-04-19 09:05:42,705] INFO user.views: Успешный вход: test@example.com
[2025-04-19 09:05:42,706] WARNING django.request: Unauthorized: /api/shop/basket/add/
[2025-04-19 09:05:42,883] INFO user.views: Попытка входа: test@example.com
[2025-04-19 09:05:43,033] INFO user.views: Успешный вход: test@example.com
[2025-04-19 09:05:43,036] WARNING shop.views: Ошибка валидации данных для добавления товара в корзину для пользователя с ID 22: {'product': [ErrorDetail(string='Invalid pk "1" - object does not exist.', code='does_not_exist')]}
[2025-04-19 09:05:43,036] WARNING django.request: Bad Request: /api/shop/basket/add/
[2025-04-19 09:05:43,216] INFO user.views: Попытка входа: test@example.com
[2025-04-19 09:05:43,365] INFO user.views: Успешный вход: test@example.com
[2025-04-19 09:05:43,368] WARNING shop.views: Ошибка валидации данных для добавления товара в корзину для пользователя с ID 23: {'product': [ErrorDetail(string='Invalid pk "0" - object does not exist.', code='does_not_exist')]}
[2025-04-19 09:05:43,368] WARNING django.request: Bad Request: /api/shop/basket/add/
[2025-04-19 09:05:43,546] INFO user.views: Попытка входа: test@example.com
[2025-04-19 09:05:43,704] INFO user.views: Успешный вход: test@example.com
[2025-04-19 09:05:43,707] WARNING shop.views: Ошибка валидации данных для добавления товара в корзину для пользователя с ID 24: {'product': [ErrorDetail(string='Invalid pk "0" - object does not exist.', code='does_not_exist')]}
[2025-04-19 09:05:43,708] WARNING django.request: Bad Request: /api/shop/basket/add/
[2025-04-19 09:05:43,886] INFO user.views: Попытка входа: test@example.com
[2025-04-19 09:05:44,036] INFO user.views: Успешный вход: test@example.com
[2025-04-19 09:05:44,039] WARNING shop.views: Ошибка валидации данных для добавления товара в корзину для пользователя с ID 25: {'product': [ErrorDetail(string='Invalid pk "-1" - object does not exist.', code='does_not_exist')], 'quantity': [ErrorDetail(string='Ensure this value is greater than or equal to 0.', code='min_value')]}
[2025-04-19 09:05:44,039] WARNING django.request: Bad Request: /api/shop/basket/add/
[2025-04-19 09:05:44,222] INFO user.views: Попытка входа: test@example.com
[2025-04-19 09:05:44,373] INFO user.views: Успешный вход: test@example.com
[2025-04-19 09:05:44,375] INFO shop.signals: Изменения или удаление категории с ID 2. Очистка кеша категорий.
[2025-04-19 09:05:44,910] INFO user.views: Попытка входа: test@example.com
[2025-04-19 09:05:45,084] INFO user.views: Успешный вход: test@example.com
[2025-04-19 09:05:45,088] WARNING django.request: Not Found: /api/shop/basket/remove/1/
[2025-04-19 09:05:45,092] WARNING django.request: Unauthorized: /api/shop/basket/remove/1/
[2025-04-19 09:05:45,250] INFO user.views: Попытка входа: test@example.com
[2025-04-19 09:05:45,424] INFO user.views: Успешный вход: test@example.com
[2025-04-19 09:05:45,427] INFO user_profile.views: Попытка смены пароля для пользователя с ID 28
[2025-04-19 09:05:45,758] INFO user_profile.views: Пароль успешно изменён для пользователя с ID 28
[2025-04-19 09:05:46,065] INFO user.views: Попытка входа: test@example.com
[2025-04-19 09:05:46,241] INFO user.views: Успешный вход: test@example.com
[2025-04-19 09:05:46,243] INFO user_profile.views: Попытка смены пароля для пользователя с ID 29
[2025-04-19 09:05:46,391] WARNING user_profile.views: Ошибка валидации данных для пользователя с ID 29: {'old_password': [ErrorDetail(string='Неверный текущий пароль', code='invalid')]}
[2025-04-19 09:05:46,391] WARNING django.request: Bad Request: /api/profile/change-password/
[2025-04-19 09:05:46,551] INFO user.views: Попытка входа: test@example.com
[2025-04-19 09:05:46,701] INFO user.views: Успешный вход: test@example.com
[2025-04-19 09:05:46,703] WARNING django.request: Unauthorized: /api/profile/change-password/
[2025-04-19 09:05:46,875] INFO user.views: Попытка входа: test@example.com
[2025-04-19 09:05:47,053] INFO user.views: Успешный вход: test@example.com
[2025-04-19 09:05:47,056] INFO user_profile.views: Попытка смены пароля для пользователя с ID 31
[2025-04-19 09:05:47,208] WARNING user_profile.views: Ошибка валидации данных для пользователя с ID 31: {'new_password': [ErrorDetail(string='This password is too short. It must contain at least 8 characters.', code='password_too_short'), ErrorDetail(string='This password is too common.', code='password_too_common'), ErrorDetail(string='This password is entirely numeric.', code='password_entirely_numeric')]}
[2025-04-19 09:05:47,208] WARNING django.request: Bad Request: /api/profile/change-password/
[2025-04-19 09:05:47,393] INFO user.views: Попытка входа: test@example.com
[2025-04-19 09:05:47,574] INFO user.views: Успешный вход: test@example.com
[2025-04-19 09:05:47,576] INFO user_profile.views: Попытка смены пароля для пользователя с ID 32
[2025-04-19 09:05:47,724] WARNING user_profile.views: Ошибка валидации данных для пользователя с ID 32: {'new_password': [ErrorDetail(string='This password is too common.', code='password_too_common'), ErrorDetail(string='This password is entirely numeric.', code='password_entirely_numeric')]}
[2025-04-19 09:05:47,724] WARNING django.request: Bad Request: /api/profile/change-password/
[2025-04-19 09:05:47,886] INFO user.views: Попытка входа: test@example.com
[2025-04-19 09:05:48,037] INFO user.views: Успешный вход: test@example.com
[2025-04-19 09:05:48,039] INFO user_profile.views: Попытка смены пароля для пользователя с ID 33
[2025-04-19 09:05:48,207] WARNING user_profile.views: Ошибка валидации данных для пользователя с ID 33: {'new_password': [ErrorDetail(string='This password is too short. It must contain at least 8 characters.', code='password_too_short'), ErrorDetail(string='This password is too common.', code='password_too_common')]}
[2025-04-19 09:05:48,207] WARNING django.request: Bad Request: /api/profile/change-password/
[2025-04-19 09:05:48,369] INFO user.views: Попытка входа: test@example.com
[2025-04-19 09:05:48,520] INFO user.views: Успешный вход: test@example.com
[2025-04-19 09:05:48,522] INFO user_profile.views: Попытка смены пароля для пользователя с ID 34
[2025-04-19 09:05:48,669] WARNING user_profile.views: Ошибка валидации данных для пользователя с ID 34: {'new_password': [ErrorDetail(string='This password is too common.', code='password_too_common')]}
[2025-04-19 09:05:48,669] WARNING django.request: Bad Request: /api/profile/change-password/
[2025-04-19 09:05:48,839] INFO user.views: Попытка входа: test@example.com
[2025-04-19 09:05:48,989] INFO user.views: Успешный вход: test@example.com
[2025-04-19 09:05:48,991] INFO user_profile.views: Запрос информации о пользователе сессии для пользователя с ID 35
[2025-04-19 09:05:48,992] INFO user_profile.views: Информация о пользователе с ID 35 успешно получена
[2025-04-19 09:05:49,151] INFO user.views: Попытка входа: test@example.com
[2025-04-19 09:05:49,307] INFO user.views: Успешный вход: test@example.com
[2025-04-19 09:05:49,309] WARNING django.request: Unauthorized: /api/profile/me/
[2025-04-19 09:05:49,313] INFO shop.signals: Изменения или удаление категории с ID 3. Очистка кеша категорий.
[2025-04-19 09:05:49,504] INFO shop.signals: Изменения или удаление категории с ID 4. Очистка кеша категорий.
[2025-04-19 09:05:49,668] INFO shop.views: Запрос на поиск продуктов с фильтрами
[2025-04-19 09:05:49,668] INFO shop.views: Поиск с параметрами: search=laptop, filters={'min_price': 1000, 'max_price': 3000, 'category': 1}, page=1, page_size=10
[2025-04-19 09:05:49,668] INFO shop.utils.cache: Сформирован ключ кеша: products_search_5bd592b289d19d541a914daf7650b780
[2025-04-19 09:05:49,669] ERROR django.request: Internal Server Error: /api/shop/products/filters/
Traceback (most recent call last):
  File "/usr/local/lib/python3.12/site-packages/django_redis/cache.py", line 29, in _decorator
    return method(self, *args, **kwargs)
           ^^^^^^^^^^^^^^^^^^^^^^^^^^^^^
  File "/usr/local/lib/python3.12/site-packages/django_redis/cache.py", line 99, in _get
    return self.client.get(key, default=default, version=version, client=client)
           ^^^^^^^^^^^^^^^^^^^^^^^^^^^^^^^^^^^^^^^^^^^^^^^^^^^^^^^^^^^^^^^^^^^^^
  File "/usr/local/lib/python3.12/site-packages/django_redis/client/default.py", line 260, in get
    raise ConnectionInterrupted(connection=client) from e
django_redis.exceptions.ConnectionInterrupted: Redis ConnectionError: Error 111 connecting to localhost:6379. Connection refused.

During handling of the above exception, another exception occurred:

Traceback (most recent call last):
  File "/usr/local/lib/python3.12/site-packages/django/core/handlers/exception.py", line 55, in inner
    response = get_response(request)
               ^^^^^^^^^^^^^^^^^^^^^
  File "/usr/local/lib/python3.12/site-packages/django/core/handlers/base.py", line 197, in _get_response
    response = wrapped_callback(request, *callback_args, **callback_kwargs)
               ^^^^^^^^^^^^^^^^^^^^^^^^^^^^^^^^^^^^^^^^^^^^^^^^^^^^^^^^^^^^
  File "/usr/local/lib/python3.12/site-packages/django/views/decorators/csrf.py", line 65, in _view_wrapper
    return view_func(request, *args, **kwargs)
           ^^^^^^^^^^^^^^^^^^^^^^^^^^^^^^^^^^^
  File "/usr/local/lib/python3.12/site-packages/django/views/generic/base.py", line 104, in view
    return self.dispatch(request, *args, **kwargs)
           ^^^^^^^^^^^^^^^^^^^^^^^^^^^^^^^^^^^^^^^
  File "/usr/local/lib/python3.12/site-packages/rest_framework/views.py", line 509, in dispatch
    response = self.handle_exception(exc)
               ^^^^^^^^^^^^^^^^^^^^^^^^^^
  File "/usr/local/lib/python3.12/site-packages/rest_framework/views.py", line 469, in handle_exception
    self.raise_uncaught_exception(exc)
  File "/usr/local/lib/python3.12/site-packages/rest_framework/views.py", line 480, in raise_uncaught_exception
    raise exc
  File "/usr/local/lib/python3.12/site-packages/rest_framework/views.py", line 506, in dispatch
    response = handler(request, *args, **kwargs)
               ^^^^^^^^^^^^^^^^^^^^^^^^^^^^^^^^^
  File "/backend/shop/views.py", line 84, in post
    return get_cached_list_response(
           ^^^^^^^^^^^^^^^^^^^^^^^^^
  File "/backend/shop/utils/cache.py", line 27, in get_cached_list_response
    cached_data = cache.get(cache_key)
                  ^^^^^^^^^^^^^^^^^^^^
  File "/usr/local/lib/python3.12/site-packages/django_redis/cache.py", line 92, in get
    value = self._get(key, default, version, client)
            ^^^^^^^^^^^^^^^^^^^^^^^^^^^^^^^^^^^^^^^^
  File "/usr/local/lib/python3.12/site-packages/django_redis/cache.py", line 36, in _decorator
    raise e.__cause__
  File "/usr/local/lib/python3.12/site-packages/django_redis/client/default.py", line 258, in get
    value = client.get(key)
            ^^^^^^^^^^^^^^^
  File "/usr/local/lib/python3.12/site-packages/redis/commands/core.py", line 1822, in get
    return self.execute_command("GET", name, keys=[name])
           ^^^^^^^^^^^^^^^^^^^^^^^^^^^^^^^^^^^^^^^^^^^^^^
  File "/usr/local/lib/python3.12/site-packages/redis/client.py", line 559, in execute_command
    return self._execute_command(*args, **options)
           ^^^^^^^^^^^^^^^^^^^^^^^^^^^^^^^^^^^^^^^
  File "/usr/local/lib/python3.12/site-packages/redis/client.py", line 565, in _execute_command
    conn = self.connection or pool.get_connection(command_name, **options)
                              ^^^^^^^^^^^^^^^^^^^^^^^^^^^^^^^^^^^^^^^^^^^^
  File "/usr/local/lib/python3.12/site-packages/redis/connection.py", line 1422, in get_connection
    connection.connect()
  File "/usr/local/lib/python3.12/site-packages/redis/connection.py", line 363, in connect
    raise ConnectionError(self._error_message(e))
redis.exceptions.ConnectionError: Error 111 connecting to localhost:6379. Connection refused.
[2025-04-19 09:05:49,829] INFO shop.views: Запрос на поиск продуктов с фильтрами
[2025-04-19 09:05:49,829] INFO shop.views: Поиск с параметрами: search=shirt, filters={'min_price': 10, 'max_price': 100, 'category': 2}, page=1, page_size=20
[2025-04-19 09:05:49,829] INFO shop.utils.cache: Сформирован ключ кеша: products_search_7bd415631b68454ad8d99e0a7fd91675
[2025-04-19 09:05:49,830] ERROR django.request: Internal Server Error: /api/shop/products/filters/
Traceback (most recent call last):
  File "/usr/local/lib/python3.12/site-packages/django_redis/cache.py", line 29, in _decorator
    return method(self, *args, **kwargs)
           ^^^^^^^^^^^^^^^^^^^^^^^^^^^^^
  File "/usr/local/lib/python3.12/site-packages/django_redis/cache.py", line 99, in _get
    return self.client.get(key, default=default, version=version, client=client)
           ^^^^^^^^^^^^^^^^^^^^^^^^^^^^^^^^^^^^^^^^^^^^^^^^^^^^^^^^^^^^^^^^^^^^^
  File "/usr/local/lib/python3.12/site-packages/django_redis/client/default.py", line 260, in get
    raise ConnectionInterrupted(connection=client) from e
django_redis.exceptions.ConnectionInterrupted: Redis ConnectionError: Error 111 connecting to localhost:6379. Connection refused.

During handling of the above exception, another exception occurred:

Traceback (most recent call last):
  File "/usr/local/lib/python3.12/site-packages/django/core/handlers/exception.py", line 55, in inner
    response = get_response(request)
               ^^^^^^^^^^^^^^^^^^^^^
  File "/usr/local/lib/python3.12/site-packages/django/core/handlers/base.py", line 197, in _get_response
    response = wrapped_callback(request, *callback_args, **callback_kwargs)
               ^^^^^^^^^^^^^^^^^^^^^^^^^^^^^^^^^^^^^^^^^^^^^^^^^^^^^^^^^^^^
  File "/usr/local/lib/python3.12/site-packages/django/views/decorators/csrf.py", line 65, in _view_wrapper
    return view_func(request, *args, **kwargs)
           ^^^^^^^^^^^^^^^^^^^^^^^^^^^^^^^^^^^
  File "/usr/local/lib/python3.12/site-packages/django/views/generic/base.py", line 104, in view
    return self.dispatch(request, *args, **kwargs)
           ^^^^^^^^^^^^^^^^^^^^^^^^^^^^^^^^^^^^^^^
  File "/usr/local/lib/python3.12/site-packages/rest_framework/views.py", line 509, in dispatch
    response = self.handle_exception(exc)
               ^^^^^^^^^^^^^^^^^^^^^^^^^^
  File "/usr/local/lib/python3.12/site-packages/rest_framework/views.py", line 469, in handle_exception
    self.raise_uncaught_exception(exc)
  File "/usr/local/lib/python3.12/site-packages/rest_framework/views.py", line 480, in raise_uncaught_exception
    raise exc
  File "/usr/local/lib/python3.12/site-packages/rest_framework/views.py", line 506, in dispatch
    response = handler(request, *args, **kwargs)
               ^^^^^^^^^^^^^^^^^^^^^^^^^^^^^^^^^
  File "/backend/shop/views.py", line 84, in post
    return get_cached_list_response(
           ^^^^^^^^^^^^^^^^^^^^^^^^^
  File "/backend/shop/utils/cache.py", line 27, in get_cached_list_response
    cached_data = cache.get(cache_key)
                  ^^^^^^^^^^^^^^^^^^^^
  File "/usr/local/lib/python3.12/site-packages/django_redis/cache.py", line 92, in get
    value = self._get(key, default, version, client)
            ^^^^^^^^^^^^^^^^^^^^^^^^^^^^^^^^^^^^^^^^
  File "/usr/local/lib/python3.12/site-packages/django_redis/cache.py", line 36, in _decorator
    raise e.__cause__
  File "/usr/local/lib/python3.12/site-packages/django_redis/client/default.py", line 258, in get
    value = client.get(key)
            ^^^^^^^^^^^^^^^
  File "/usr/local/lib/python3.12/site-packages/redis/commands/core.py", line 1822, in get
    return self.execute_command("GET", name, keys=[name])
           ^^^^^^^^^^^^^^^^^^^^^^^^^^^^^^^^^^^^^^^^^^^^^^
  File "/usr/local/lib/python3.12/site-packages/redis/client.py", line 559, in execute_command
    return self._execute_command(*args, **options)
           ^^^^^^^^^^^^^^^^^^^^^^^^^^^^^^^^^^^^^^^
  File "/usr/local/lib/python3.12/site-packages/redis/client.py", line 565, in _execute_command
    conn = self.connection or pool.get_connection(command_name, **options)
                              ^^^^^^^^^^^^^^^^^^^^^^^^^^^^^^^^^^^^^^^^^^^^
  File "/usr/local/lib/python3.12/site-packages/redis/connection.py", line 1422, in get_connection
    connection.connect()
  File "/usr/local/lib/python3.12/site-packages/redis/connection.py", line 363, in connect
    raise ConnectionError(self._error_message(e))
redis.exceptions.ConnectionError: Error 111 connecting to localhost:6379. Connection refused.
[2025-04-19 09:05:49,994] INFO shop.views: Запрос на поиск продуктов с фильтрами
[2025-04-19 09:05:49,995] INFO shop.views: Поиск с параметрами: search=book, filters={'min_price': 0, 'max_price': 50, 'category': 5}, page=1, page_size=5
[2025-04-19 09:05:49,995] INFO shop.utils.cache: Сформирован ключ кеша: products_search_c1ca3b8dcd5d21ce1ea6666a1a0af7a9
[2025-04-19 09:05:49,995] ERROR django.request: Internal Server Error: /api/shop/products/filters/
Traceback (most recent call last):
  File "/usr/local/lib/python3.12/site-packages/django_redis/cache.py", line 29, in _decorator
    return method(self, *args, **kwargs)
           ^^^^^^^^^^^^^^^^^^^^^^^^^^^^^
  File "/usr/local/lib/python3.12/site-packages/django_redis/cache.py", line 99, in _get
    return self.client.get(key, default=default, version=version, client=client)
           ^^^^^^^^^^^^^^^^^^^^^^^^^^^^^^^^^^^^^^^^^^^^^^^^^^^^^^^^^^^^^^^^^^^^^
  File "/usr/local/lib/python3.12/site-packages/django_redis/client/default.py", line 260, in get
    raise ConnectionInterrupted(connection=client) from e
django_redis.exceptions.ConnectionInterrupted: Redis ConnectionError: Error 111 connecting to localhost:6379. Connection refused.

During handling of the above exception, another exception occurred:

Traceback (most recent call last):
  File "/usr/local/lib/python3.12/site-packages/django/core/handlers/exception.py", line 55, in inner
    response = get_response(request)
               ^^^^^^^^^^^^^^^^^^^^^
  File "/usr/local/lib/python3.12/site-packages/django/core/handlers/base.py", line 197, in _get_response
    response = wrapped_callback(request, *callback_args, **callback_kwargs)
               ^^^^^^^^^^^^^^^^^^^^^^^^^^^^^^^^^^^^^^^^^^^^^^^^^^^^^^^^^^^^
  File "/usr/local/lib/python3.12/site-packages/django/views/decorators/csrf.py", line 65, in _view_wrapper
    return view_func(request, *args, **kwargs)
           ^^^^^^^^^^^^^^^^^^^^^^^^^^^^^^^^^^^
  File "/usr/local/lib/python3.12/site-packages/django/views/generic/base.py", line 104, in view
    return self.dispatch(request, *args, **kwargs)
           ^^^^^^^^^^^^^^^^^^^^^^^^^^^^^^^^^^^^^^^
  File "/usr/local/lib/python3.12/site-packages/rest_framework/views.py", line 509, in dispatch
    response = self.handle_exception(exc)
               ^^^^^^^^^^^^^^^^^^^^^^^^^^
  File "/usr/local/lib/python3.12/site-packages/rest_framework/views.py", line 469, in handle_exception
    self.raise_uncaught_exception(exc)
  File "/usr/local/lib/python3.12/site-packages/rest_framework/views.py", line 480, in raise_uncaught_exception
    raise exc
  File "/usr/local/lib/python3.12/site-packages/rest_framework/views.py", line 506, in dispatch
    response = handler(request, *args, **kwargs)
               ^^^^^^^^^^^^^^^^^^^^^^^^^^^^^^^^^
  File "/backend/shop/views.py", line 84, in post
    return get_cached_list_response(
           ^^^^^^^^^^^^^^^^^^^^^^^^^
  File "/backend/shop/utils/cache.py", line 27, in get_cached_list_response
    cached_data = cache.get(cache_key)
                  ^^^^^^^^^^^^^^^^^^^^
  File "/usr/local/lib/python3.12/site-packages/django_redis/cache.py", line 92, in get
    value = self._get(key, default, version, client)
            ^^^^^^^^^^^^^^^^^^^^^^^^^^^^^^^^^^^^^^^^
  File "/usr/local/lib/python3.12/site-packages/django_redis/cache.py", line 36, in _decorator
    raise e.__cause__
  File "/usr/local/lib/python3.12/site-packages/django_redis/client/default.py", line 258, in get
    value = client.get(key)
            ^^^^^^^^^^^^^^^
  File "/usr/local/lib/python3.12/site-packages/redis/commands/core.py", line 1822, in get
    return self.execute_command("GET", name, keys=[name])
           ^^^^^^^^^^^^^^^^^^^^^^^^^^^^^^^^^^^^^^^^^^^^^^
  File "/usr/local/lib/python3.12/site-packages/redis/client.py", line 559, in execute_command
    return self._execute_command(*args, **options)
           ^^^^^^^^^^^^^^^^^^^^^^^^^^^^^^^^^^^^^^^
  File "/usr/local/lib/python3.12/site-packages/redis/client.py", line 565, in _execute_command
    conn = self.connection or pool.get_connection(command_name, **options)
                              ^^^^^^^^^^^^^^^^^^^^^^^^^^^^^^^^^^^^^^^^^^^^
  File "/usr/local/lib/python3.12/site-packages/redis/connection.py", line 1422, in get_connection
    connection.connect()
  File "/usr/local/lib/python3.12/site-packages/redis/connection.py", line 363, in connect
    raise ConnectionError(self._error_message(e))
redis.exceptions.ConnectionError: Error 111 connecting to localhost:6379. Connection refused.
[2025-04-19 09:05:50,150] INFO shop.views: Запрос на поиск продуктов с фильтрами
[2025-04-19 09:05:50,150] INFO shop.views: Поиск с параметрами: search=, filters={'min_price': 0, 'max_price': 0}, page=1, page_size=10
[2025-04-19 09:05:50,151] INFO shop.utils.cache: Сформирован ключ кеша: products_search_3c39a522a23da0d4cc15d7d77b551645
[2025-04-19 09:05:50,151] ERROR django.request: Internal Server Error: /api/shop/products/filters/
Traceback (most recent call last):
  File "/usr/local/lib/python3.12/site-packages/django_redis/cache.py", line 29, in _decorator
    return method(self, *args, **kwargs)
           ^^^^^^^^^^^^^^^^^^^^^^^^^^^^^
  File "/usr/local/lib/python3.12/site-packages/django_redis/cache.py", line 99, in _get
    return self.client.get(key, default=default, version=version, client=client)
           ^^^^^^^^^^^^^^^^^^^^^^^^^^^^^^^^^^^^^^^^^^^^^^^^^^^^^^^^^^^^^^^^^^^^^
  File "/usr/local/lib/python3.12/site-packages/django_redis/client/default.py", line 260, in get
    raise ConnectionInterrupted(connection=client) from e
django_redis.exceptions.ConnectionInterrupted: Redis ConnectionError: Error 111 connecting to localhost:6379. Connection refused.

During handling of the above exception, another exception occurred:

Traceback (most recent call last):
  File "/usr/local/lib/python3.12/site-packages/django/core/handlers/exception.py", line 55, in inner
    response = get_response(request)
               ^^^^^^^^^^^^^^^^^^^^^
  File "/usr/local/lib/python3.12/site-packages/django/core/handlers/base.py", line 197, in _get_response
    response = wrapped_callback(request, *callback_args, **callback_kwargs)
               ^^^^^^^^^^^^^^^^^^^^^^^^^^^^^^^^^^^^^^^^^^^^^^^^^^^^^^^^^^^^
  File "/usr/local/lib/python3.12/site-packages/django/views/decorators/csrf.py", line 65, in _view_wrapper
    return view_func(request, *args, **kwargs)
           ^^^^^^^^^^^^^^^^^^^^^^^^^^^^^^^^^^^
  File "/usr/local/lib/python3.12/site-packages/django/views/generic/base.py", line 104, in view
    return self.dispatch(request, *args, **kwargs)
           ^^^^^^^^^^^^^^^^^^^^^^^^^^^^^^^^^^^^^^^
  File "/usr/local/lib/python3.12/site-packages/rest_framework/views.py", line 509, in dispatch
    response = self.handle_exception(exc)
               ^^^^^^^^^^^^^^^^^^^^^^^^^^
  File "/usr/local/lib/python3.12/site-packages/rest_framework/views.py", line 469, in handle_exception
    self.raise_uncaught_exception(exc)
  File "/usr/local/lib/python3.12/site-packages/rest_framework/views.py", line 480, in raise_uncaught_exception
    raise exc
  File "/usr/local/lib/python3.12/site-packages/rest_framework/views.py", line 506, in dispatch
    response = handler(request, *args, **kwargs)
               ^^^^^^^^^^^^^^^^^^^^^^^^^^^^^^^^^
  File "/backend/shop/views.py", line 84, in post
    return get_cached_list_response(
           ^^^^^^^^^^^^^^^^^^^^^^^^^
  File "/backend/shop/utils/cache.py", line 27, in get_cached_list_response
    cached_data = cache.get(cache_key)
                  ^^^^^^^^^^^^^^^^^^^^
  File "/usr/local/lib/python3.12/site-packages/django_redis/cache.py", line 92, in get
    value = self._get(key, default, version, client)
            ^^^^^^^^^^^^^^^^^^^^^^^^^^^^^^^^^^^^^^^^
  File "/usr/local/lib/python3.12/site-packages/django_redis/cache.py", line 36, in _decorator
    raise e.__cause__
  File "/usr/local/lib/python3.12/site-packages/django_redis/client/default.py", line 258, in get
    value = client.get(key)
            ^^^^^^^^^^^^^^^
  File "/usr/local/lib/python3.12/site-packages/redis/commands/core.py", line 1822, in get
    return self.execute_command("GET", name, keys=[name])
           ^^^^^^^^^^^^^^^^^^^^^^^^^^^^^^^^^^^^^^^^^^^^^^
  File "/usr/local/lib/python3.12/site-packages/redis/client.py", line 559, in execute_command
    return self._execute_command(*args, **options)
           ^^^^^^^^^^^^^^^^^^^^^^^^^^^^^^^^^^^^^^^
  File "/usr/local/lib/python3.12/site-packages/redis/client.py", line 565, in _execute_command
    conn = self.connection or pool.get_connection(command_name, **options)
                              ^^^^^^^^^^^^^^^^^^^^^^^^^^^^^^^^^^^^^^^^^^^^
  File "/usr/local/lib/python3.12/site-packages/redis/connection.py", line 1422, in get_connection
    connection.connect()
  File "/usr/local/lib/python3.12/site-packages/redis/connection.py", line 363, in connect
    raise ConnectionError(self._error_message(e))
redis.exceptions.ConnectionError: Error 111 connecting to localhost:6379. Connection refused.
[2025-04-19 09:05:50,328] INFO shop.views: Запрос на поиск продуктов с фильтрами
[2025-04-19 09:05:50,329] INFO shop.views: Поиск с параметрами: search=gaming, filters={'min_price': 200, 'max_price': 1500, 'category': 87}, page=1, page_size=15
[2025-04-19 09:05:50,329] INFO shop.utils.cache: Сформирован ключ кеша: products_search_84f733e7a29c9601f995d8487c8a7ae5
[2025-04-19 09:05:50,330] ERROR django.request: Internal Server Error: /api/shop/products/filters/
Traceback (most recent call last):
  File "/usr/local/lib/python3.12/site-packages/django_redis/cache.py", line 29, in _decorator
    return method(self, *args, **kwargs)
           ^^^^^^^^^^^^^^^^^^^^^^^^^^^^^
  File "/usr/local/lib/python3.12/site-packages/django_redis/cache.py", line 99, in _get
    return self.client.get(key, default=default, version=version, client=client)
           ^^^^^^^^^^^^^^^^^^^^^^^^^^^^^^^^^^^^^^^^^^^^^^^^^^^^^^^^^^^^^^^^^^^^^
  File "/usr/local/lib/python3.12/site-packages/django_redis/client/default.py", line 260, in get
    raise ConnectionInterrupted(connection=client) from e
django_redis.exceptions.ConnectionInterrupted: Redis ConnectionError: Error 111 connecting to localhost:6379. Connection refused.

During handling of the above exception, another exception occurred:

Traceback (most recent call last):
  File "/usr/local/lib/python3.12/site-packages/django/core/handlers/exception.py", line 55, in inner
    response = get_response(request)
               ^^^^^^^^^^^^^^^^^^^^^
  File "/usr/local/lib/python3.12/site-packages/django/core/handlers/base.py", line 197, in _get_response
    response = wrapped_callback(request, *callback_args, **callback_kwargs)
               ^^^^^^^^^^^^^^^^^^^^^^^^^^^^^^^^^^^^^^^^^^^^^^^^^^^^^^^^^^^^
  File "/usr/local/lib/python3.12/site-packages/django/views/decorators/csrf.py", line 65, in _view_wrapper
    return view_func(request, *args, **kwargs)
           ^^^^^^^^^^^^^^^^^^^^^^^^^^^^^^^^^^^
  File "/usr/local/lib/python3.12/site-packages/django/views/generic/base.py", line 104, in view
    return self.dispatch(request, *args, **kwargs)
           ^^^^^^^^^^^^^^^^^^^^^^^^^^^^^^^^^^^^^^^
  File "/usr/local/lib/python3.12/site-packages/rest_framework/views.py", line 509, in dispatch
    response = self.handle_exception(exc)
               ^^^^^^^^^^^^^^^^^^^^^^^^^^
  File "/usr/local/lib/python3.12/site-packages/rest_framework/views.py", line 469, in handle_exception
    self.raise_uncaught_exception(exc)
  File "/usr/local/lib/python3.12/site-packages/rest_framework/views.py", line 480, in raise_uncaught_exception
    raise exc
  File "/usr/local/lib/python3.12/site-packages/rest_framework/views.py", line 506, in dispatch
    response = handler(request, *args, **kwargs)
               ^^^^^^^^^^^^^^^^^^^^^^^^^^^^^^^^^
  File "/backend/shop/views.py", line 84, in post
    return get_cached_list_response(
           ^^^^^^^^^^^^^^^^^^^^^^^^^
  File "/backend/shop/utils/cache.py", line 27, in get_cached_list_response
    cached_data = cache.get(cache_key)
                  ^^^^^^^^^^^^^^^^^^^^
  File "/usr/local/lib/python3.12/site-packages/django_redis/cache.py", line 92, in get
    value = self._get(key, default, version, client)
            ^^^^^^^^^^^^^^^^^^^^^^^^^^^^^^^^^^^^^^^^
  File "/usr/local/lib/python3.12/site-packages/django_redis/cache.py", line 36, in _decorator
    raise e.__cause__
  File "/usr/local/lib/python3.12/site-packages/django_redis/client/default.py", line 258, in get
    value = client.get(key)
            ^^^^^^^^^^^^^^^
  File "/usr/local/lib/python3.12/site-packages/redis/commands/core.py", line 1822, in get
    return self.execute_command("GET", name, keys=[name])
           ^^^^^^^^^^^^^^^^^^^^^^^^^^^^^^^^^^^^^^^^^^^^^^
  File "/usr/local/lib/python3.12/site-packages/redis/client.py", line 559, in execute_command
    return self._execute_command(*args, **options)
           ^^^^^^^^^^^^^^^^^^^^^^^^^^^^^^^^^^^^^^^
  File "/usr/local/lib/python3.12/site-packages/redis/client.py", line 565, in _execute_command
    conn = self.connection or pool.get_connection(command_name, **options)
                              ^^^^^^^^^^^^^^^^^^^^^^^^^^^^^^^^^^^^^^^^^^^^
  File "/usr/local/lib/python3.12/site-packages/redis/connection.py", line 1422, in get_connection
    connection.connect()
  File "/usr/local/lib/python3.12/site-packages/redis/connection.py", line 363, in connect
    raise ConnectionError(self._error_message(e))
redis.exceptions.ConnectionError: Error 111 connecting to localhost:6379. Connection refused.
[2025-04-19 09:05:50,498] INFO shop.views: Запрос на поиск продуктов с фильтрами
[2025-04-19 09:05:50,499] INFO shop.views: Поиск с параметрами: search=headphones, filters={'min_price': 50, 'max_price': 500, 'category': 2}, page=1, page_size=12
[2025-04-19 09:05:50,499] INFO shop.utils.cache: Сформирован ключ кеша: products_search_a8a364d33e2c18ef6be0a7c7ccc521a7
[2025-04-19 09:05:50,499] ERROR django.request: Internal Server Error: /api/shop/products/filters/
Traceback (most recent call last):
  File "/usr/local/lib/python3.12/site-packages/django_redis/cache.py", line 29, in _decorator
    return method(self, *args, **kwargs)
           ^^^^^^^^^^^^^^^^^^^^^^^^^^^^^
  File "/usr/local/lib/python3.12/site-packages/django_redis/cache.py", line 99, in _get
    return self.client.get(key, default=default, version=version, client=client)
           ^^^^^^^^^^^^^^^^^^^^^^^^^^^^^^^^^^^^^^^^^^^^^^^^^^^^^^^^^^^^^^^^^^^^^
  File "/usr/local/lib/python3.12/site-packages/django_redis/client/default.py", line 260, in get
    raise ConnectionInterrupted(connection=client) from e
django_redis.exceptions.ConnectionInterrupted: Redis ConnectionError: Error 111 connecting to localhost:6379. Connection refused.

During handling of the above exception, another exception occurred:

Traceback (most recent call last):
  File "/usr/local/lib/python3.12/site-packages/django/core/handlers/exception.py", line 55, in inner
    response = get_response(request)
               ^^^^^^^^^^^^^^^^^^^^^
  File "/usr/local/lib/python3.12/site-packages/django/core/handlers/base.py", line 197, in _get_response
    response = wrapped_callback(request, *callback_args, **callback_kwargs)
               ^^^^^^^^^^^^^^^^^^^^^^^^^^^^^^^^^^^^^^^^^^^^^^^^^^^^^^^^^^^^
  File "/usr/local/lib/python3.12/site-packages/django/views/decorators/csrf.py", line 65, in _view_wrapper
    return view_func(request, *args, **kwargs)
           ^^^^^^^^^^^^^^^^^^^^^^^^^^^^^^^^^^^
  File "/usr/local/lib/python3.12/site-packages/django/views/generic/base.py", line 104, in view
    return self.dispatch(request, *args, **kwargs)
           ^^^^^^^^^^^^^^^^^^^^^^^^^^^^^^^^^^^^^^^
  File "/usr/local/lib/python3.12/site-packages/rest_framework/views.py", line 509, in dispatch
    response = self.handle_exception(exc)
               ^^^^^^^^^^^^^^^^^^^^^^^^^^
  File "/usr/local/lib/python3.12/site-packages/rest_framework/views.py", line 469, in handle_exception
    self.raise_uncaught_exception(exc)
  File "/usr/local/lib/python3.12/site-packages/rest_framework/views.py", line 480, in raise_uncaught_exception
    raise exc
  File "/usr/local/lib/python3.12/site-packages/rest_framework/views.py", line 506, in dispatch
    response = handler(request, *args, **kwargs)
               ^^^^^^^^^^^^^^^^^^^^^^^^^^^^^^^^^
  File "/backend/shop/views.py", line 84, in post
    return get_cached_list_response(
           ^^^^^^^^^^^^^^^^^^^^^^^^^
  File "/backend/shop/utils/cache.py", line 27, in get_cached_list_response
    cached_data = cache.get(cache_key)
                  ^^^^^^^^^^^^^^^^^^^^
  File "/usr/local/lib/python3.12/site-packages/django_redis/cache.py", line 92, in get
    value = self._get(key, default, version, client)
            ^^^^^^^^^^^^^^^^^^^^^^^^^^^^^^^^^^^^^^^^
  File "/usr/local/lib/python3.12/site-packages/django_redis/cache.py", line 36, in _decorator
    raise e.__cause__
  File "/usr/local/lib/python3.12/site-packages/django_redis/client/default.py", line 258, in get
    value = client.get(key)
            ^^^^^^^^^^^^^^^
  File "/usr/local/lib/python3.12/site-packages/redis/commands/core.py", line 1822, in get
    return self.execute_command("GET", name, keys=[name])
           ^^^^^^^^^^^^^^^^^^^^^^^^^^^^^^^^^^^^^^^^^^^^^^
  File "/usr/local/lib/python3.12/site-packages/redis/client.py", line 559, in execute_command
    return self._execute_command(*args, **options)
           ^^^^^^^^^^^^^^^^^^^^^^^^^^^^^^^^^^^^^^^
  File "/usr/local/lib/python3.12/site-packages/redis/client.py", line 565, in _execute_command
    conn = self.connection or pool.get_connection(command_name, **options)
                              ^^^^^^^^^^^^^^^^^^^^^^^^^^^^^^^^^^^^^^^^^^^^
  File "/usr/local/lib/python3.12/site-packages/redis/connection.py", line 1422, in get_connection
    connection.connect()
  File "/usr/local/lib/python3.12/site-packages/redis/connection.py", line 363, in connect
    raise ConnectionError(self._error_message(e))
redis.exceptions.ConnectionError: Error 111 connecting to localhost:6379. Connection refused.
[2025-04-19 09:05:50,654] INFO shop.views: Запрос на поиск продуктов с фильтрами
[2025-04-19 09:05:50,655] INFO shop.views: Поиск с параметрами: search=shoes, filters={'min_price': 30, 'max_price': 300, 'category': 6}, page=1, page_size=10
[2025-04-19 09:05:50,655] INFO shop.utils.cache: Сформирован ключ кеша: products_search_d686a04b5d37198db860d5dadcef5c29
[2025-04-19 09:05:50,656] ERROR django.request: Internal Server Error: /api/shop/products/filters/
Traceback (most recent call last):
  File "/usr/local/lib/python3.12/site-packages/django_redis/cache.py", line 29, in _decorator
    return method(self, *args, **kwargs)
           ^^^^^^^^^^^^^^^^^^^^^^^^^^^^^
  File "/usr/local/lib/python3.12/site-packages/django_redis/cache.py", line 99, in _get
    return self.client.get(key, default=default, version=version, client=client)
           ^^^^^^^^^^^^^^^^^^^^^^^^^^^^^^^^^^^^^^^^^^^^^^^^^^^^^^^^^^^^^^^^^^^^^
  File "/usr/local/lib/python3.12/site-packages/django_redis/client/default.py", line 260, in get
    raise ConnectionInterrupted(connection=client) from e
django_redis.exceptions.ConnectionInterrupted: Redis ConnectionError: Error 111 connecting to localhost:6379. Connection refused.

During handling of the above exception, another exception occurred:

Traceback (most recent call last):
  File "/usr/local/lib/python3.12/site-packages/django/core/handlers/exception.py", line 55, in inner
    response = get_response(request)
               ^^^^^^^^^^^^^^^^^^^^^
  File "/usr/local/lib/python3.12/site-packages/django/core/handlers/base.py", line 197, in _get_response
    response = wrapped_callback(request, *callback_args, **callback_kwargs)
               ^^^^^^^^^^^^^^^^^^^^^^^^^^^^^^^^^^^^^^^^^^^^^^^^^^^^^^^^^^^^
  File "/usr/local/lib/python3.12/site-packages/django/views/decorators/csrf.py", line 65, in _view_wrapper
    return view_func(request, *args, **kwargs)
           ^^^^^^^^^^^^^^^^^^^^^^^^^^^^^^^^^^^
  File "/usr/local/lib/python3.12/site-packages/django/views/generic/base.py", line 104, in view
    return self.dispatch(request, *args, **kwargs)
           ^^^^^^^^^^^^^^^^^^^^^^^^^^^^^^^^^^^^^^^
  File "/usr/local/lib/python3.12/site-packages/rest_framework/views.py", line 509, in dispatch
    response = self.handle_exception(exc)
               ^^^^^^^^^^^^^^^^^^^^^^^^^^
  File "/usr/local/lib/python3.12/site-packages/rest_framework/views.py", line 469, in handle_exception
    self.raise_uncaught_exception(exc)
  File "/usr/local/lib/python3.12/site-packages/rest_framework/views.py", line 480, in raise_uncaught_exception
    raise exc
  File "/usr/local/lib/python3.12/site-packages/rest_framework/views.py", line 506, in dispatch
    response = handler(request, *args, **kwargs)
               ^^^^^^^^^^^^^^^^^^^^^^^^^^^^^^^^^
  File "/backend/shop/views.py", line 84, in post
    return get_cached_list_response(
           ^^^^^^^^^^^^^^^^^^^^^^^^^
  File "/backend/shop/utils/cache.py", line 27, in get_cached_list_response
    cached_data = cache.get(cache_key)
                  ^^^^^^^^^^^^^^^^^^^^
  File "/usr/local/lib/python3.12/site-packages/django_redis/cache.py", line 92, in get
    value = self._get(key, default, version, client)
            ^^^^^^^^^^^^^^^^^^^^^^^^^^^^^^^^^^^^^^^^
  File "/usr/local/lib/python3.12/site-packages/django_redis/cache.py", line 36, in _decorator
    raise e.__cause__
  File "/usr/local/lib/python3.12/site-packages/django_redis/client/default.py", line 258, in get
    value = client.get(key)
            ^^^^^^^^^^^^^^^
  File "/usr/local/lib/python3.12/site-packages/redis/commands/core.py", line 1822, in get
    return self.execute_command("GET", name, keys=[name])
           ^^^^^^^^^^^^^^^^^^^^^^^^^^^^^^^^^^^^^^^^^^^^^^
  File "/usr/local/lib/python3.12/site-packages/redis/client.py", line 559, in execute_command
    return self._execute_command(*args, **options)
           ^^^^^^^^^^^^^^^^^^^^^^^^^^^^^^^^^^^^^^^
  File "/usr/local/lib/python3.12/site-packages/redis/client.py", line 565, in _execute_command
    conn = self.connection or pool.get_connection(command_name, **options)
                              ^^^^^^^^^^^^^^^^^^^^^^^^^^^^^^^^^^^^^^^^^^^^
  File "/usr/local/lib/python3.12/site-packages/redis/connection.py", line 1422, in get_connection
    connection.connect()
  File "/usr/local/lib/python3.12/site-packages/redis/connection.py", line 363, in connect
    raise ConnectionError(self._error_message(e))
redis.exceptions.ConnectionError: Error 111 connecting to localhost:6379. Connection refused.
[2025-04-19 09:05:50,830] INFO shop.views: Запрос на поиск продуктов с фильтрами
[2025-04-19 09:05:50,830] INFO shop.views: Поиск с параметрами: search=t-shirt, filters={'min_price': 5, 'max_price': 50, 'category': 4}, page=1, page_size=25
[2025-04-19 09:05:50,830] INFO shop.utils.cache: Сформирован ключ кеша: products_search_270738e61e55dcc7e51a97ee92b61f4c
[2025-04-19 09:05:50,831] ERROR django.request: Internal Server Error: /api/shop/products/filters/
Traceback (most recent call last):
  File "/usr/local/lib/python3.12/site-packages/django_redis/cache.py", line 29, in _decorator
    return method(self, *args, **kwargs)
           ^^^^^^^^^^^^^^^^^^^^^^^^^^^^^
  File "/usr/local/lib/python3.12/site-packages/django_redis/cache.py", line 99, in _get
    return self.client.get(key, default=default, version=version, client=client)
           ^^^^^^^^^^^^^^^^^^^^^^^^^^^^^^^^^^^^^^^^^^^^^^^^^^^^^^^^^^^^^^^^^^^^^
  File "/usr/local/lib/python3.12/site-packages/django_redis/client/default.py", line 260, in get
    raise ConnectionInterrupted(connection=client) from e
django_redis.exceptions.ConnectionInterrupted: Redis ConnectionError: Error 111 connecting to localhost:6379. Connection refused.

During handling of the above exception, another exception occurred:

Traceback (most recent call last):
  File "/usr/local/lib/python3.12/site-packages/django/core/handlers/exception.py", line 55, in inner
    response = get_response(request)
               ^^^^^^^^^^^^^^^^^^^^^
  File "/usr/local/lib/python3.12/site-packages/django/core/handlers/base.py", line 197, in _get_response
    response = wrapped_callback(request, *callback_args, **callback_kwargs)
               ^^^^^^^^^^^^^^^^^^^^^^^^^^^^^^^^^^^^^^^^^^^^^^^^^^^^^^^^^^^^
  File "/usr/local/lib/python3.12/site-packages/django/views/decorators/csrf.py", line 65, in _view_wrapper
    return view_func(request, *args, **kwargs)
           ^^^^^^^^^^^^^^^^^^^^^^^^^^^^^^^^^^^
  File "/usr/local/lib/python3.12/site-packages/django/views/generic/base.py", line 104, in view
    return self.dispatch(request, *args, **kwargs)
           ^^^^^^^^^^^^^^^^^^^^^^^^^^^^^^^^^^^^^^^
  File "/usr/local/lib/python3.12/site-packages/rest_framework/views.py", line 509, in dispatch
    response = self.handle_exception(exc)
               ^^^^^^^^^^^^^^^^^^^^^^^^^^
  File "/usr/local/lib/python3.12/site-packages/rest_framework/views.py", line 469, in handle_exception
    self.raise_uncaught_exception(exc)
  File "/usr/local/lib/python3.12/site-packages/rest_framework/views.py", line 480, in raise_uncaught_exception
    raise exc
  File "/usr/local/lib/python3.12/site-packages/rest_framework/views.py", line 506, in dispatch
    response = handler(request, *args, **kwargs)
               ^^^^^^^^^^^^^^^^^^^^^^^^^^^^^^^^^
  File "/backend/shop/views.py", line 84, in post
    return get_cached_list_response(
           ^^^^^^^^^^^^^^^^^^^^^^^^^
  File "/backend/shop/utils/cache.py", line 27, in get_cached_list_response
    cached_data = cache.get(cache_key)
                  ^^^^^^^^^^^^^^^^^^^^
  File "/usr/local/lib/python3.12/site-packages/django_redis/cache.py", line 92, in get
    value = self._get(key, default, version, client)
            ^^^^^^^^^^^^^^^^^^^^^^^^^^^^^^^^^^^^^^^^
  File "/usr/local/lib/python3.12/site-packages/django_redis/cache.py", line 36, in _decorator
    raise e.__cause__
  File "/usr/local/lib/python3.12/site-packages/django_redis/client/default.py", line 258, in get
    value = client.get(key)
            ^^^^^^^^^^^^^^^
  File "/usr/local/lib/python3.12/site-packages/redis/commands/core.py", line 1822, in get
    return self.execute_command("GET", name, keys=[name])
           ^^^^^^^^^^^^^^^^^^^^^^^^^^^^^^^^^^^^^^^^^^^^^^
  File "/usr/local/lib/python3.12/site-packages/redis/client.py", line 559, in execute_command
    return self._execute_command(*args, **options)
           ^^^^^^^^^^^^^^^^^^^^^^^^^^^^^^^^^^^^^^^
  File "/usr/local/lib/python3.12/site-packages/redis/client.py", line 565, in _execute_command
    conn = self.connection or pool.get_connection(command_name, **options)
                              ^^^^^^^^^^^^^^^^^^^^^^^^^^^^^^^^^^^^^^^^^^^^
  File "/usr/local/lib/python3.12/site-packages/redis/connection.py", line 1422, in get_connection
    connection.connect()
  File "/usr/local/lib/python3.12/site-packages/redis/connection.py", line 363, in connect
    raise ConnectionError(self._error_message(e))
redis.exceptions.ConnectionError: Error 111 connecting to localhost:6379. Connection refused.
[2025-04-19 09:05:51,005] INFO shop.views: Запрос на поиск продуктов с фильтрами
[2025-04-19 09:05:51,005] INFO shop.views: Поиск с параметрами: search=chair, filters={'min_price': 100, 'max_price': 1000, 'category': 3}, page=1, page_size=10
[2025-04-19 09:05:51,005] INFO shop.utils.cache: Сформирован ключ кеша: products_search_ea2bc50c4d2c2e0ecccc74f73ac3cdaf
[2025-04-19 09:05:51,006] ERROR django.request: Internal Server Error: /api/shop/products/filters/
Traceback (most recent call last):
  File "/usr/local/lib/python3.12/site-packages/django_redis/cache.py", line 29, in _decorator
    return method(self, *args, **kwargs)
           ^^^^^^^^^^^^^^^^^^^^^^^^^^^^^
  File "/usr/local/lib/python3.12/site-packages/django_redis/cache.py", line 99, in _get
    return self.client.get(key, default=default, version=version, client=client)
           ^^^^^^^^^^^^^^^^^^^^^^^^^^^^^^^^^^^^^^^^^^^^^^^^^^^^^^^^^^^^^^^^^^^^^
  File "/usr/local/lib/python3.12/site-packages/django_redis/client/default.py", line 260, in get
    raise ConnectionInterrupted(connection=client) from e
django_redis.exceptions.ConnectionInterrupted: Redis ConnectionError: Error 111 connecting to localhost:6379. Connection refused.

During handling of the above exception, another exception occurred:

Traceback (most recent call last):
  File "/usr/local/lib/python3.12/site-packages/django/core/handlers/exception.py", line 55, in inner
    response = get_response(request)
               ^^^^^^^^^^^^^^^^^^^^^
  File "/usr/local/lib/python3.12/site-packages/django/core/handlers/base.py", line 197, in _get_response
    response = wrapped_callback(request, *callback_args, **callback_kwargs)
               ^^^^^^^^^^^^^^^^^^^^^^^^^^^^^^^^^^^^^^^^^^^^^^^^^^^^^^^^^^^^
  File "/usr/local/lib/python3.12/site-packages/django/views/decorators/csrf.py", line 65, in _view_wrapper
    return view_func(request, *args, **kwargs)
           ^^^^^^^^^^^^^^^^^^^^^^^^^^^^^^^^^^^
  File "/usr/local/lib/python3.12/site-packages/django/views/generic/base.py", line 104, in view
    return self.dispatch(request, *args, **kwargs)
           ^^^^^^^^^^^^^^^^^^^^^^^^^^^^^^^^^^^^^^^
  File "/usr/local/lib/python3.12/site-packages/rest_framework/views.py", line 509, in dispatch
    response = self.handle_exception(exc)
               ^^^^^^^^^^^^^^^^^^^^^^^^^^
  File "/usr/local/lib/python3.12/site-packages/rest_framework/views.py", line 469, in handle_exception
    self.raise_uncaught_exception(exc)
  File "/usr/local/lib/python3.12/site-packages/rest_framework/views.py", line 480, in raise_uncaught_exception
    raise exc
  File "/usr/local/lib/python3.12/site-packages/rest_framework/views.py", line 506, in dispatch
    response = handler(request, *args, **kwargs)
               ^^^^^^^^^^^^^^^^^^^^^^^^^^^^^^^^^
  File "/backend/shop/views.py", line 84, in post
    return get_cached_list_response(
           ^^^^^^^^^^^^^^^^^^^^^^^^^
  File "/backend/shop/utils/cache.py", line 27, in get_cached_list_response
    cached_data = cache.get(cache_key)
                  ^^^^^^^^^^^^^^^^^^^^
  File "/usr/local/lib/python3.12/site-packages/django_redis/cache.py", line 92, in get
    value = self._get(key, default, version, client)
            ^^^^^^^^^^^^^^^^^^^^^^^^^^^^^^^^^^^^^^^^
  File "/usr/local/lib/python3.12/site-packages/django_redis/cache.py", line 36, in _decorator
    raise e.__cause__
  File "/usr/local/lib/python3.12/site-packages/django_redis/client/default.py", line 258, in get
    value = client.get(key)
            ^^^^^^^^^^^^^^^
  File "/usr/local/lib/python3.12/site-packages/redis/commands/core.py", line 1822, in get
    return self.execute_command("GET", name, keys=[name])
           ^^^^^^^^^^^^^^^^^^^^^^^^^^^^^^^^^^^^^^^^^^^^^^
  File "/usr/local/lib/python3.12/site-packages/redis/client.py", line 559, in execute_command
    return self._execute_command(*args, **options)
           ^^^^^^^^^^^^^^^^^^^^^^^^^^^^^^^^^^^^^^^
  File "/usr/local/lib/python3.12/site-packages/redis/client.py", line 565, in _execute_command
    conn = self.connection or pool.get_connection(command_name, **options)
                              ^^^^^^^^^^^^^^^^^^^^^^^^^^^^^^^^^^^^^^^^^^^^
  File "/usr/local/lib/python3.12/site-packages/redis/connection.py", line 1422, in get_connection
    connection.connect()
  File "/usr/local/lib/python3.12/site-packages/redis/connection.py", line 363, in connect
    raise ConnectionError(self._error_message(e))
redis.exceptions.ConnectionError: Error 111 connecting to localhost:6379. Connection refused.
[2025-04-19 09:05:51,177] INFO shop.views: Запрос на поиск продуктов с фильтрами
[2025-04-19 09:05:51,178] INFO shop.views: Поиск с параметрами: search=, filters={'min_price': 0, 'max_price': 10000}, page=1, page_size=100
[2025-04-19 09:05:51,178] INFO shop.utils.cache: Сформирован ключ кеша: products_search_09b47c3b82178ced1401b94cf18b444e
[2025-04-19 09:05:51,178] ERROR django.request: Internal Server Error: /api/shop/products/filters/
Traceback (most recent call last):
  File "/usr/local/lib/python3.12/site-packages/django_redis/cache.py", line 29, in _decorator
    return method(self, *args, **kwargs)
           ^^^^^^^^^^^^^^^^^^^^^^^^^^^^^
  File "/usr/local/lib/python3.12/site-packages/django_redis/cache.py", line 99, in _get
    return self.client.get(key, default=default, version=version, client=client)
           ^^^^^^^^^^^^^^^^^^^^^^^^^^^^^^^^^^^^^^^^^^^^^^^^^^^^^^^^^^^^^^^^^^^^^
  File "/usr/local/lib/python3.12/site-packages/django_redis/client/default.py", line 260, in get
    raise ConnectionInterrupted(connection=client) from e
django_redis.exceptions.ConnectionInterrupted: Redis ConnectionError: Error 111 connecting to localhost:6379. Connection refused.

During handling of the above exception, another exception occurred:

Traceback (most recent call last):
  File "/usr/local/lib/python3.12/site-packages/django/core/handlers/exception.py", line 55, in inner
    response = get_response(request)
               ^^^^^^^^^^^^^^^^^^^^^
  File "/usr/local/lib/python3.12/site-packages/django/core/handlers/base.py", line 197, in _get_response
    response = wrapped_callback(request, *callback_args, **callback_kwargs)
               ^^^^^^^^^^^^^^^^^^^^^^^^^^^^^^^^^^^^^^^^^^^^^^^^^^^^^^^^^^^^
  File "/usr/local/lib/python3.12/site-packages/django/views/decorators/csrf.py", line 65, in _view_wrapper
    return view_func(request, *args, **kwargs)
           ^^^^^^^^^^^^^^^^^^^^^^^^^^^^^^^^^^^
  File "/usr/local/lib/python3.12/site-packages/django/views/generic/base.py", line 104, in view
    return self.dispatch(request, *args, **kwargs)
           ^^^^^^^^^^^^^^^^^^^^^^^^^^^^^^^^^^^^^^^
  File "/usr/local/lib/python3.12/site-packages/rest_framework/views.py", line 509, in dispatch
    response = self.handle_exception(exc)
               ^^^^^^^^^^^^^^^^^^^^^^^^^^
  File "/usr/local/lib/python3.12/site-packages/rest_framework/views.py", line 469, in handle_exception
    self.raise_uncaught_exception(exc)
  File "/usr/local/lib/python3.12/site-packages/rest_framework/views.py", line 480, in raise_uncaught_exception
    raise exc
  File "/usr/local/lib/python3.12/site-packages/rest_framework/views.py", line 506, in dispatch
    response = handler(request, *args, **kwargs)
               ^^^^^^^^^^^^^^^^^^^^^^^^^^^^^^^^^
  File "/backend/shop/views.py", line 84, in post
    return get_cached_list_response(
           ^^^^^^^^^^^^^^^^^^^^^^^^^
  File "/backend/shop/utils/cache.py", line 27, in get_cached_list_response
    cached_data = cache.get(cache_key)
                  ^^^^^^^^^^^^^^^^^^^^
  File "/usr/local/lib/python3.12/site-packages/django_redis/cache.py", line 92, in get
    value = self._get(key, default, version, client)
            ^^^^^^^^^^^^^^^^^^^^^^^^^^^^^^^^^^^^^^^^
  File "/usr/local/lib/python3.12/site-packages/django_redis/cache.py", line 36, in _decorator
    raise e.__cause__
  File "/usr/local/lib/python3.12/site-packages/django_redis/client/default.py", line 258, in get
    value = client.get(key)
            ^^^^^^^^^^^^^^^
  File "/usr/local/lib/python3.12/site-packages/redis/commands/core.py", line 1822, in get
    return self.execute_command("GET", name, keys=[name])
           ^^^^^^^^^^^^^^^^^^^^^^^^^^^^^^^^^^^^^^^^^^^^^^
  File "/usr/local/lib/python3.12/site-packages/redis/client.py", line 559, in execute_command
    return self._execute_command(*args, **options)
           ^^^^^^^^^^^^^^^^^^^^^^^^^^^^^^^^^^^^^^^
  File "/usr/local/lib/python3.12/site-packages/redis/client.py", line 565, in _execute_command
    conn = self.connection or pool.get_connection(command_name, **options)
                              ^^^^^^^^^^^^^^^^^^^^^^^^^^^^^^^^^^^^^^^^^^^^
  File "/usr/local/lib/python3.12/site-packages/redis/connection.py", line 1422, in get_connection
    connection.connect()
  File "/usr/local/lib/python3.12/site-packages/redis/connection.py", line 363, in connect
    raise ConnectionError(self._error_message(e))
redis.exceptions.ConnectionError: Error 111 connecting to localhost:6379. Connection refused.
[2025-04-19 09:05:51,635] INFO user.views: Попытка входа: test@example.com
[2025-04-19 09:05:51,791] INFO user.views: Успешный вход: test@example.com
[2025-04-19 09:05:51,801] WARNING django.request: Unauthorized: /api/token/refresh/
[2025-04-19 09:05:51,803] WARNING django.request: Bad Request: /api/token/refresh/
[2025-04-19 09:05:51,959] INFO user.views: Попытка входа: test@example.com
[2025-04-19 09:05:52,109] INFO user.views: Успешный вход: test@example.com
[2025-04-19 09:05:52,114] WARNING django.request: Unauthorized: /api/token/verify/
[2025-04-19 09:05:52,279] INFO user.views: Получение списка пользователей
[2025-04-19 09:05:52,439] WARNING user.views: Удаление пользователя с ID: 40
[2025-04-19 09:05:52,601] INFO user.views: Получение пользователя по ID: 41
[2025-04-19 09:05:52,605] INFO user.views: Попытка входа: 
[2025-04-19 09:05:52,606] WARNING django.request: Bad Request: /api/auth/login/
[2025-04-19 09:05:52,607] INFO user.views: Попытка входа: test@example.com
[2025-04-19 09:05:52,607] WARNING django.request: Bad Request: /api/auth/login/
[2025-04-19 09:05:52,608] INFO user.views: Попытка входа: 
[2025-04-19 09:05:52,608] WARNING django.request: Bad Request: /api/auth/login/
[2025-04-19 09:11:20,447] INFO user.views: Попытка входа: 
[2025-04-19 09:11:20,448] WARNING django.request: Bad Request: /api/auth/login/
[2025-04-19 09:11:20,451] INFO user.views: Попытка входа: test@example.com
[2025-04-19 09:11:20,451] WARNING django.request: Bad Request: /api/auth/login/
[2025-04-19 09:11:20,452] INFO user.views: Попытка входа: 
[2025-04-19 09:11:20,452] WARNING django.request: Bad Request: /api/auth/login/
[2025-04-19 09:14:27,039] ERROR user.tasks: Ошибка при отправке письма подтверждения для user_id=16: CustomUser matching query does not exist.
[2025-04-19 09:17:51,260] ERROR user.tasks: Ошибка при отправке письма подтверждения для user_id=16: CustomUser matching query does not exist.
